Workbook
Name Abkürzungen: Teams[TID]
Name Abkürzungen: Teams[TID]
Name Ergebnis: #REF!
Name Gegner: #REF!
Name Gruppe: #REF!
Name GSOG: #REF!
Name GSUG: #REF!
Name HeimGast: #REF!
Name HZ: #REF!
Name MinuteOG: #REF!
Name MinuteUG: #REF!
Name Nummern: Spieler[Nr]
Name Phase: #REF!
Name PROG: #REF!
Name PRUG: #REF!
Name Spiel: #REF!
Name Spielerliste: #REF!
Name SpielNr.: #REF!
Name SpieltagOG: #REF!
Name SpieltagUG: #REF!
Name Team: #REF!

Sheet Spiele
A1: SID | B1: Datum | C1: Heim | D1: Gast | E1: 1. HZ | F1: 2. HZ | G1: TH | H1: TG | I1: PH | J1: PG
A2: 1 | B2: 45900 | C2: FCN | D2: GWD | E2: 40 | F2: 40 | G2: =SUM(COUNTIFS(Abschlüsse!$A$2:$A$3098,$A2,Abschlüsse!$B$2:$B$3098,$C2,Abschlüsse!$L$2:$L$3098,"Tor"),COUNTIFS(Abschlüsse!$A$2:$A$3098,$A2,Abschlüsse!$B$2:$B$3098,$C2,Abschlüsse!$L$2:$L$3098,"ET")) -> 4 | H2: =SUM(COUNTIFS(Abschlüsse!$A$2:$A$3098,$A2,Abschlüsse!$B$2:$B$3098,$D2,Abschlüsse!$L$2:$L$3098,"Tor"),COUNTIFS(Abschlüsse!$A$2:$A$3098,$A2,Abschlüsse!$B$2:$B$3098,$D2,Abschlüsse!$L$2:$L$3098,"ET")) -> 0 | I2: =IF($A2="","",IF($G2>$H2,3,IF($G2=$H2,1,IF($G2<$H2,0,"")))) -> 3 | J2: =IF($A2="","",IF($G2<$H2,3,IF($G2=$H2,1,IF($G2>$H2,0,"")))) -> 0
A3: 2 | B3: 45906 | C3: FCD | D3: FCN | E3: 40 | F3: 43 | G3: =SUM(COUNTIFS(Abschlüsse!$A$2:$A$3098,$A3,Abschlüsse!$B$2:$B$3098,$C3,Abschlüsse!$L$2:$L$3098,"Tor"),COUNTIFS(Abschlüsse!$A$2:$A$3098,$A3,Abschlüsse!$B$2:$B$3098,$C3,Abschlüsse!$L$2:$L$3098,"ET")) -> 2 | H3: =SUM(COUNTIFS(Abschlüsse!$A$2:$A$3098,$A3,Abschlüsse!$B$2:$B$3098,$D3,Abschlüsse!$L$2:$L$3098,"Tor"),COUNTIFS(Abschlüsse!$A$2:$A$3098,$A3,Abschlüsse!$B$2:$B$3098,$D3,Abschlüsse!$L$2:$L$3098,"ET")) -> 3 | I3: =IF($A3="","",IF($G3>$H3,3,IF($G3=$H3,1,IF($G3<$H3,0,"")))) -> 0 | J3: =IF($A3="","",IF($G3<$H3,3,IF($G3=$H3,1,IF($G3>$H3,0,"")))) -> 3
A4: 3 | B4: 45914 | C4: FCN | D4: TSV | E4: 40 | F4: 40 | G4: =SUM(COUNTIFS(Abschlüsse!$A$2:$A$3098,$A4,Abschlüsse!$B$2:$B$3098,$C4,Abschlüsse!$L$2:$L$3098,"Tor"),COUNTIFS(Abschlüsse!$A$2:$A$3098,$A4,Abschlüsse!$B$2:$B$3098,$C4,Abschlüsse!$L$2:$L$3098,"ET")) -> 4 | H4: =SUM(COUNTIFS(Abschlüsse!$A$2:$A$3098,$A4,Abschlüsse!$B$2:$B$3098,$D4,Abschlüsse!$L$2:$L$3098,"Tor"),COUNTIFS(Abschlüsse!$A$2:$A$3098,$A4,Abschlüsse!$B$2:$B$3098,$D4,Abschlüsse!$L$2:$L$3098,"ET")) -> 1 | I4: =IF($A4="","",IF($G4>$H4,3,IF($G4=$H4,1,IF($G4<$H4,0,"")))) -> 3 | J4: =IF($A4="","",IF($G4<$H4,3,IF($G4=$H4,1,IF($G4>$H4,0,"")))) -> 0
A5: 4 | B5: 45917 | C5: DJK | D5: FCN | E5: 42 | F5: 43 | G5: =SUM(COUNTIFS(Abschlüsse!$A$2:$A$3098,$A5,Abschlüsse!$B$2:$B$3098,$C5,Abschlüsse!$L$2:$L$3098,"Tor"),COUNTIFS(Abschlüsse!$A$2:$A$3098,$A5,Abschlüsse!$B$2:$B$3098,$C5,Abschlüsse!$L$2:$L$3098,"ET")) -> 0 | H5: =SUM(COUNTIFS(Abschlüsse!$A$2:$A$3098,$A5,Abschlüsse!$B$2:$B$3098,$D5,Abschlüsse!$L$2:$L$3098,"Tor"),COUNTIFS(Abschlüsse!$A$2:$A$3098,$A5,Abschlüsse!$B$2:$B$3098,$D5,Abschlüsse!$L$2:$L$3098,"ET")) -> 2 | I5: =IF($A5="","",IF($G5>$H5,3,IF($G5=$H5,1,IF($G5<$H5,0,"")))) -> 0 | J5: =IF($A5="","",IF($G5<$H5,3,IF($G5=$H5,1,IF($G5>$H5,0,"")))) -> 3
A6: 5 | B6: 45921 | C6: FCN | D6: FCM | E6: 41 | F6: 42 | G6: =SUM(COUNTIFS(Abschlüsse!$A$2:$A$3098,$A6,Abschlüsse!$B$2:$B$3098,$C6,Abschlüsse!$L$2:$L$3098,"Tor"),COUNTIFS(Abschlüsse!$A$2:$A$3098,$A6,Abschlüsse!$B$2:$B$3098,$C6,Abschlüsse!$L$2:$L$3098,"ET")) -> 2 | H6: =SUM(COUNTIFS(Abschlüsse!$A$2:$A$3098,$A6,Abschlüsse!$B$2:$B$3098,$D6,Abschlüsse!$L$2:$L$3098,"Tor"),COUNTIFS(Abschlüsse!$A$2:$A$3098,$A6,Abschlüsse!$B$2:$B$3098,$D6,Abschlüsse!$L$2:$L$3098,"ET")) -> 2 | I6: =IF($A6="","",IF($G6>$H6,3,IF($G6=$H6,1,IF($G6<$H6,0,"")))) -> 1 | J6: =IF($A6="","",IF($G6<$H6,3,IF($G6=$H6,1,IF($G6>$H6,0,"")))) -> 1
A7: 6 | B7: 45928 | C7: FWK | D7: FCN | E7: 41 | F7: 45 | G7: =SUM(COUNTIFS(Abschlüsse!$A$2:$A$3098,$A7,Abschlüsse!$B$2:$B$3098,$C7,Abschlüsse!$L$2:$L$3098,"Tor"),COUNTIFS(Abschlüsse!$A$2:$A$3098,$A7,Abschlüsse!$B$2:$B$3098,$C7,Abschlüsse!$L$2:$L$3098,"ET")) -> 4 | H7: =SUM(COUNTIFS(Abschlüsse!$A$2:$A$3098,$A7,Abschlüsse!$B$2:$B$3098,$D7,Abschlüsse!$L$2:$L$3098,"Tor"),COUNTIFS(Abschlüsse!$A$2:$A$3098,$A7,Abschlüsse!$B$2:$B$3098,$D7,Abschlüsse!$L$2:$L$3098,"ET")) -> 4 | I7: =IF($A7="","",IF($G7>$H7,3,IF($G7=$H7,1,IF($G7<$H7,0,"")))) -> 1 | J7: =IF($A7="","",IF($G7<$H7,3,IF($G7=$H7,1,IF($G7>$H7,0,"")))) -> 1
A8: 7 | B8: 45931 | C8: FCN | D8: FCA | E8: 41 | F8: 45 | G8: =SUM(COUNTIFS(Abschlüsse!$A$2:$A$3098,$A8,Abschlüsse!$B$2:$B$3098,$C8,Abschlüsse!$L$2:$L$3098,"Tor"),COUNTIFS(Abschlüsse!$A$2:$A$3098,$A8,Abschlüsse!$B$2:$B$3098,$C8,Abschlüsse!$L$2:$L$3098,"ET")) -> 2 | H8: =SUM(COUNTIFS(Abschlüsse!$A$2:$A$3098,$A8,Abschlüsse!$B$2:$B$3098,$D8,Abschlüsse!$L$2:$L$3098,"Tor"),COUNTIFS(Abschlüsse!$A$2:$A$3098,$A8,Abschlüsse!$B$2:$B$3098,$D8,Abschlüsse!$L$2:$L$3098,"ET")) -> 1 | I8: =IF($A8="","",IF($G8>$H8,3,IF($G8=$H8,1,IF($G8<$H8,0,"")))) -> 3 | J8: =IF($A8="","",IF($G8<$H8,3,IF($G8=$H8,1,IF($G8>$H8,0,"")))) -> 0
A9: 8 | B9: 45935 | C9: SSV | D9: FCN | E9: 40 | F9: 46 | G9: =SUM(COUNTIFS(Abschlüsse!$A$2:$A$3098,$A9,Abschlüsse!$B$2:$B$3098,$C9,Abschlüsse!$L$2:$L$3098,"Tor"),COUNTIFS(Abschlüsse!$A$2:$A$3098,$A9,Abschlüsse!$B$2:$B$3098,$C9,Abschlüsse!$L$2:$L$3098,"ET")) -> 2 | H9: =SUM(COUNTIFS(Abschlüsse!$A$2:$A$3098,$A9,Abschlüsse!$B$2:$B$3098,$D9,Abschlüsse!$L$2:$L$3098,"Tor"),COUNTIFS(Abschlüsse!$A$2:$A$3098,$A9,Abschlüsse!$B$2:$B$3098,$D9,Abschlüsse!$L$2:$L$3098,"ET")) -> 3 | I9: =IF($A9="","",IF($G9>$H9,3,IF($G9=$H9,1,IF($G9<$H9,0,"")))) -> 0 | J9: =IF($A9="","",IF($G9<$H9,3,IF($G9=$H9,1,IF($G9>$H9,0,"")))) -> 3
A10: 9 | B10: 45949 | C10: UHG | D10: FCN | E10: 42 | F10: 44 | G10: =SUM(COUNTIFS(Abschlüsse!$A$2:$A$3098,$A10,Abschlüsse!$B$2:$B$3098,$C10,Abschlüsse!$L$2:$L$3098,"Tor"),COUNTIFS(Abschlüsse!$A$2:$A$3098,$A10,Abschlüsse!$B$2:$B$3098,$C10,Abschlüsse!$L$2:$L$3098,"ET")) -> 2 | H10: =SUM(COUNTIFS(Abschlüsse!$A$2:$A$3098,$A10,Abschlüsse!$B$2:$B$3098,$D10,Abschlüsse!$L$2:$L$3098,"Tor"),COUNTIFS(Abschlüsse!$A$2:$A$3098,$A10,Abschlüsse!$B$2:$B$3098,$D10,Abschlüsse!$L$2:$L$3098,"ET")) -> 4 | I10: =IF($A10="","",IF($G10>$H10,3,IF($G10=$H10,1,IF($G10<$H10,0,"")))) -> 0 | J10: =IF($A10="","",IF($G10<$H10,3,IF($G10=$H10,1,IF($G10>$H10,0,"")))) -> 3
A11: 10 | B11: 45956 | C11: FCN | D11: SVA | E11: 40 | F11: 44 | G11: =SUM(COUNTIFS(Abschlüsse!$A$2:$A$3098,$A11,Abschlüsse!$B$2:$B$3098,$C11,Abschlüsse!$L$2:$L$3098,"Tor"),COUNTIFS(Abschlüsse!$A$2:$A$3098,$A11,Abschlüsse!$B$2:$B$3098,$C11,Abschlüsse!$L$2:$L$3098,"ET")) -> 2 | H11: =SUM(COUNTIFS(Abschlüsse!$A$2:$A$3098,$A11,Abschlüsse!$B$2:$B$3098,$D11,Abschlüsse!$L$2:$L$3098,"Tor"),COUNTIFS(Abschlüsse!$A$2:$A$3098,$A11,Abschlüsse!$B$2:$B$3098,$D11,Abschlüsse!$L$2:$L$3098,"ET")) -> 2 | I11: =IF($A11="","",IF($G11>$H11,3,IF($G11=$H11,1,IF($G11<$H11,0,"")))) -> 1 | J11: =IF($A11="","",IF($G11<$H11,3,IF($G11=$H11,1,IF($G11>$H11,0,"")))) -> 1
A12: 11 | B12: 45963 | C12: KSC | D12: FCN | E12: 40 | F12: 46 | G12: =SUM(COUNTIFS(Abschlüsse!$A$2:$A$3098,$A12,Abschlüsse!$B$2:$B$3098,$C12,Abschlüsse!$L$2:$L$3098,"Tor"),COUNTIFS(Abschlüsse!$A$2:$A$3098,$A12,Abschlüsse!$B$2:$B$3098,$C12,Abschlüsse!$L$2:$L$3098,"ET")) -> 3 | H12: =SUM(COUNTIFS(Abschlüsse!$A$2:$A$3098,$A12,Abschlüsse!$B$2:$B$3098,$D12,Abschlüsse!$L$2:$L$3098,"Tor"),COUNTIFS(Abschlüsse!$A$2:$A$3098,$A12,Abschlüsse!$B$2:$B$3098,$D12,Abschlüsse!$L$2:$L$3098,"ET")) -> 3 | I12: =IF($A12="","",IF($G12>$H12,3,IF($G12=$H12,1,IF($G12<$H12,0,"")))) -> 1 | J12: =IF($A12="","",IF($G12<$H12,3,IF($G12=$H12,1,IF($G12>$H12,0,"")))) -> 1
A13: 12 | B13: 45970 | C13: FCN | D13: FCB | E13: 41 | F13: 45 | G13: =SUM(COUNTIFS(Abschlüsse!$A$2:$A$3098,$A13,Abschlüsse!$B$2:$B$3098,$C13,Abschlüsse!$L$2:$L$3098,"Tor"),COUNTIFS(Abschlüsse!$A$2:$A$3098,$A13,Abschlüsse!$B$2:$B$3098,$C13,Abschlüsse!$L$2:$L$3098,"ET")) -> 5 | H13: =SUM(COUNTIFS(Abschlüsse!$A$2:$A$3098,$A13,Abschlüsse!$B$2:$B$3098,$D13,Abschlüsse!$L$2:$L$3098,"Tor"),COUNTIFS(Abschlüsse!$A$2:$A$3098,$A13,Abschlüsse!$B$2:$B$3098,$D13,Abschlüsse!$L$2:$L$3098,"ET")) -> 6 | I13: =IF($A13="","",IF($G13>$H13,3,IF($G13=$H13,1,IF($G13<$H13,0,"")))) -> 0 | J13: =IF($A13="","",IF($G13<$H13,3,IF($G13=$H13,1,IF($G13>$H13,0,"")))) -> 3
... A16: 15 | B16: 45710 | C16: FCN | D16: FCD | E16: 45 | F16: 44 | G16: =SUM(COUNTIFS(Abschlüsse!$A$2:$A$3098,$A16,Abschlüsse!$B$2:$B$3098,$C16,Abschlüsse!$L$2:$L$3098,"Tor"),COUNTIFS(Abschlüsse!$A$2:$A$3098,$A16,Abschlüsse!$B$2:$B$3098,$C16,Abschlüsse!$L$2:$L$3098,"ET")) -> 1 | H16: =SUM(COUNTIFS(Abschlüsse!$A$2:$A$3098,$A16,Abschlüsse!$B$2:$B$3098,$D16,Abschlüsse!$L$2:$L$3098,"Tor"),COUNTIFS(Abschlüsse!$A$2:$A$3098,$A16,Abschlüsse!$B$2:$B$3098,$D16,Abschlüsse!$L$2:$L$3098,"ET")) -> 2 | I16: =IF($A16="","",IF($G16>$H16,3,IF($G16=$H16,1,IF($G16<$H16,0,"")))) -> 0 | J16: =IF($A16="","",IF($G16<$H16,3,IF($G16=$H16,1,IF($G16>$H16,0,"")))) -> 3

Sheet Spielzeiten
A1: SID | B1: Nr | C1: 1Von | D1: 1Bis | E1: 2Von | F1: 2Bis | G1: SZ
A2: 1 | B2: 1 | C2: 1 | D2: 40 | E2: 41 | F2: 80 | G2: =SUM(Tabelle10[[#This Row],[1Bis]],Tabelle10[[#This Row],[2Bis]])-SUM(Tabelle10[[#This Row],[1Von]],Tabelle10[[#This Row],[2Von]])+IF(Tabelle10[[#This Row],[2Von]]>0,1)+IF(Tabelle10[[#This Row],[1Von]]>0,1) -> 80
A3: 1 | B3: 13 | C3: 1 | D3: 40 | E3: 41 | F3: 80 | G3: =SUM(Tabelle10[[#This Row],[1Bis]],Tabelle10[[#This Row],[2Bis]])-SUM(Tabelle10[[#This Row],[1Von]],Tabelle10[[#This Row],[2Von]])+IF(Tabelle10[[#This Row],[2Von]]>0,1)+IF(Tabelle10[[#This Row],[1Von]]>0,1) -> 80
A4: 1 | B4: 20 | C4: 1 | D4: 40 | E4: 41 | F4: 80 | G4: =SUM(Tabelle10[[#This Row],[1Bis]],Tabelle10[[#This Row],[2Bis]])-SUM(Tabelle10[[#This Row],[1Von]],Tabelle10[[#This Row],[2Von]])+IF(Tabelle10[[#This Row],[2Von]]>0,1)+IF(Tabelle10[[#This Row],[1Von]]>0,1) -> 80
A5: 1 | B5: 26 | C5: 1 | D5: 40 | E5: 41 | F5: 80 | G5: =SUM(Tabelle10[[#This Row],[1Bis]],Tabelle10[[#This Row],[2Bis]])-SUM(Tabelle10[[#This Row],[1Von]],Tabelle10[[#This Row],[2Von]])+IF(Tabelle10[[#This Row],[2Von]]>0,1)+IF(Tabelle10[[#This Row],[1Von]]>0,1) -> 80
A6: 1 | B6: 23 | C6: 1 | D6: 40 | E6: 41 | F6: 70 | G6: =SUM(Tabelle10[[#This Row],[1Bis]],Tabelle10[[#This Row],[2Bis]])-SUM(Tabelle10[[#This Row],[1Von]],Tabelle10[[#This Row],[2Von]])+IF(Tabelle10[[#This Row],[2Von]]>0,1)+IF(Tabelle10[[#This Row],[1Von]]>0,1) -> 70
A7: 1 | B7: 6 | C7: 1 | D7: 40 | E7: 41 | F7: 80 | G7: =SUM(Tabelle10[[#This Row],[1Bis]],Tabelle10[[#This Row],[2Bis]])-SUM(Tabelle10[[#This Row],[1Von]],Tabelle10[[#This Row],[2Von]])+IF(Tabelle10[[#This Row],[2Von]]>0,1)+IF(Tabelle10[[#This Row],[1Von]]>0,1) -> 80
A8: 1 | B8: 11 | C8: 1 | D8: 40 | E8: 41 | F8: 49 | G8: =SUM(Tabelle10[[#This Row],[1Bis]],Tabelle10[[#This Row],[2Bis]])-SUM(Tabelle10[[#This Row],[1Von]],Tabelle10[[#This Row],[2Von]])+IF(Tabelle10[[#This Row],[2Von]]>0,1)+IF(Tabelle10[[#This Row],[1Von]]>0,1) -> 49
A9: 1 | B9: 27 | C9: 1 | D9: 40 | E9: 41 | F9: 49 | G9: =SUM(Tabelle10[[#This Row],[1Bis]],Tabelle10[[#This Row],[2Bis]])-SUM(Tabelle10[[#This Row],[1Von]],Tabelle10[[#This Row],[2Von]])+IF(Tabelle10[[#This Row],[2Von]]>0,1)+IF(Tabelle10[[#This Row],[1Von]]>0,1) -> 49
A10: 1 | B10: 8 | C10: 1 | D10: 40 | E10: 41 | F10: 80 | G10: =SUM(Tabelle10[[#This Row],[1Bis]],Tabelle10[[#This Row],[2Bis]])-SUM(Tabelle10[[#This Row],[1Von]],Tabelle10[[#This Row],[2Von]])+IF(Tabelle10[[#This Row],[2Von]]>0,1)+IF(Tabelle10[[#This Row],[1Von]]>0,1) -> 80
A11: 1 | B11: 7 | C11: 1 | D11: 40 | E11: 41 | F11: 80 | G11: =SUM(Tabelle10[[#This Row],[1Bis]],Tabelle10[[#This Row],[2Bis]])-SUM(Tabelle10[[#This Row],[1Von]],Tabelle10[[#This Row],[2Von]])+IF(Tabelle10[[#This Row],[2Von]]>0,1)+IF(Tabelle10[[#This Row],[1Von]]>0,1) -> 80
A12: 1 | B12: 9 | C12: 1 | D12: 40 | E12: 41 | F12: 60 | G12: =SUM(Tabelle10[[#This Row],[1Bis]],Tabelle10[[#This Row],[2Bis]])-SUM(Tabelle10[[#This Row],[1Von]],Tabelle10[[#This Row],[2Von]])+IF(Tabelle10[[#This Row],[2Von]]>0,1)+IF(Tabelle10[[#This Row],[1Von]]>0,1) -> 60
A13: 1 | B13: 18 | E13: 50 | F13: 80 | G13: =SUM(Tabelle10[[#This Row],[1Bis]],Tabelle10[[#This Row],[2Bis]])-SUM(Tabelle10[[#This Row],[1Von]],Tabelle10[[#This Row],[2Von]])+IF(Tabelle10[[#This Row],[2Von]]>0,1)+IF(Tabelle10[[#This Row],[1Von]]>0,1) -> 31
A14: 1 | B14: 5 | E14: 50 | F14: 80 | G14: =SUM(Tabelle10[[#This Row],[1Bis]],Tabelle10[[#This Row],[2Bis]])-SUM(Tabelle10[[#This Row],[1Von]],Tabelle10[[#This Row],[2Von]])+IF(Tabelle10[[#This Row],[2Von]]>0,1)+IF(Tabelle10[[#This Row],[1Von]]>0,1) -> 31
A15: 1 | B15: 25 | E15: 61 | F15: 80 | G15: =SUM(Tabelle10[[#This Row],[1Bis]],Tabelle10[[#This Row],[2Bis]])-SUM(Tabelle10[[#This Row],[1Von]],Tabelle10[[#This Row],[2Von]])+IF(Tabelle10[[#This Row],[2Von]]>0,1)+IF(Tabelle10[[#This Row],[1Von]]>0,1) -> 20
A16: 1 | B16: 19 | E16: 71 | F16: 80 | G16: =SUM(Tabelle10[[#This Row],[1Bis]],Tabelle10[[#This Row],[2Bis]])-SUM(Tabelle10[[#This Row],[1Von]],Tabelle10[[#This Row],[2Von]])+IF(Tabelle10[[#This Row],[2Von]]>0,1)+IF(Tabelle10[[#This Row],[1Von]]>0,1) -> 10
A17: 2 | B17: 1 | C17: 1 | D17: 40 | E17: 41 | F17: 83 | G17: =SUM(Tabelle10[[#This Row],[1Bis]],Tabelle10[[#This Row],[2Bis]])-SUM(Tabelle10[[#This Row],[1Von]],Tabelle10[[#This Row],[2Von]])+IF(Tabelle10[[#This Row],[2Von]]>0,1)+IF(Tabelle10[[#This Row],[1Von]]>0,1) -> 83
A18: 2 | B18: 13 | C18: 1 | D18: 40 | E18: 41 | F18: 83 | G18: =SUM(Tabelle10[[#This Row],[1Bis]],Tabelle10[[#This Row],[2Bis]])-SUM(Tabelle10[[#This Row],[1Von]],Tabelle10[[#This Row],[2Von]])+IF(Tabelle10[[#This Row],[2Von]]>0,1)+IF(Tabelle10[[#This Row],[1Von]]>0,1) -> 83
A19: 2 | B19: 20 | C19: 1 | D19: 40 | E19: 41 | F19: 83 | G19: =SUM(Tabelle10[[#This Row],[1Bis]],Tabelle10[[#This Row],[2Bis]])-SUM(Tabelle10[[#This Row],[1Von]],Tabelle10[[#This Row],[2Von]])+IF(Tabelle10[[#This Row],[2Von]]>0,1)+IF(Tabelle10[[#This Row],[1Von]]>0,1) -> 83
A20: 2 | B20: 26 | C20: 1 | D20: 40 | E20: 41 | F20: 83 | G20: =SUM(Tabelle10[[#This Row],[1Bis]],Tabelle10[[#This Row],[2Bis]])-SUM(Tabelle10[[#This Row],[1Von]],Tabelle10[[#This Row],[2Von]])+IF(Tabelle10[[#This Row],[2Von]]>0,1)+IF(Tabelle10[[#This Row],[1Von]]>0,1) -> 83
A21: 2 | B21: 23 | C21: 1 | D21: 40 | E21: 41 | F21: 83 | G21: =SUM(Tabelle10[[#This Row],[1Bis]],Tabelle10[[#This Row],[2Bis]])-SUM(Tabelle10[[#This Row],[1Von]],Tabelle10[[#This Row],[2Von]])+IF(Tabelle10[[#This Row],[2Von]]>0,1)+IF(Tabelle10[[#This Row],[1Von]]>0,1) -> 83
A22: 2 | B22: 5 | C22: 1 | D22: 40 | E22: 41 | F22: 83 | G22: =SUM(Tabelle10[[#This Row],[1Bis]],Tabelle10[[#This Row],[2Bis]])-SUM(Tabelle10[[#This Row],[1Von]],Tabelle10[[#This Row],[2Von]])+IF(Tabelle10[[#This Row],[2Von]]>0,1)+IF(Tabelle10[[#This Row],[1Von]]>0,1) -> 83
A23: 2 | B23: 6 | C23: 1 | D23: 40 | E23: 41 | F23: 57 | G23: =SUM(Tabelle10[[#This Row],[1Bis]],Tabelle10[[#This Row],[2Bis]])-SUM(Tabelle10[[#This Row],[1Von]],Tabelle10[[#This Row],[2Von]])+IF(Tabelle10[[#This Row],[2Von]]>0,1)+IF(Tabelle10[[#This Row],[1Von]]>0,1) -> 57
A24: 2 | B24: 27 | C24: 1 | D24: 40 | E24: 41 | F24: 68 | G24: =SUM(Tabelle10[[#This Row],[1Bis]],Tabelle10[[#This Row],[2Bis]])-SUM(Tabelle10[[#This Row],[1Von]],Tabelle10[[#This Row],[2Von]])+IF(Tabelle10[[#This Row],[2Von]]>0,1)+IF(Tabelle10[[#This Row],[1Von]]>0,1) -> 68
A25: 2 | B25: 8 | C25: 1 | D25: 40 | E25: 41 | F25: 83 | G25: =SUM(Tabelle10[[#This Row],[1Bis]],Tabelle10[[#This Row],[2Bis]])-SUM(Tabelle10[[#This Row],[1Von]],Tabelle10[[#This Row],[2Von]])+IF(Tabelle10[[#This Row],[2Von]]>0,1)+IF(Tabelle10[[#This Row],[1Von]]>0,1) -> 83
A26: 2 | B26: 7 | C26: 1 | D26: 40 | E26: 41 | F26: 57 | G26: =SUM(Tabelle10[[#This Row],[1Bis]],Tabelle10[[#This Row],[2Bis]])-SUM(Tabelle10[[#This Row],[1Von]],Tabelle10[[#This Row],[2Von]])+IF(Tabelle10[[#This Row],[2Von]]>0,1)+IF(Tabelle10[[#This Row],[1Von]]>0,1) -> 57
A27: 2 | B27: 9 | C27: 1 | D27: 40 | E27: 41 | F27: 83 | G27: =SUM(Tabelle10[[#This Row],[1Bis]],Tabelle10[[#This Row],[2Bis]])-SUM(Tabelle10[[#This Row],[1Von]],Tabelle10[[#This Row],[2Von]])+IF(Tabelle10[[#This Row],[2Von]]>0,1)+IF(Tabelle10[[#This Row],[1Von]]>0,1) -> 83
A28: 2 | B28: 25 | E28: 58 | F28: 83 | G28: =SUM(Tabelle10[[#This Row],[1Bis]],Tabelle10[[#This Row],[2Bis]])-SUM(Tabelle10[[#This Row],[1Von]],Tabelle10[[#This Row],[2Von]])+IF(Tabelle10[[#This Row],[2Von]]>0,1)+IF(Tabelle10[[#This Row],[1Von]]>0,1) -> 26
A29: 2 | B29: 19 | E29: 58 | F29: 83 | G29: =SUM(Tabelle10[[#This Row],[1Bis]],Tabelle10[[#This Row],[2Bis]])-SUM(Tabelle10[[#This Row],[1Von]],Tabelle10[[#This Row],[2Von]])+IF(Tabelle10[[#This Row],[2Von]]>0,1)+IF(Tabelle10[[#This Row],[1Von]]>0,1) -> 26
A30: 2 | B30: 18 | E30: 69 | F30: 83 | G30: =SUM(Tabelle10[[#This Row],[1Bis]],Tabelle10[[#This Row],[2Bis]])-SUM(Tabelle10[[#This Row],[1Von]],Tabelle10[[#This Row],[2Von]])+IF(Tabelle10[[#This Row],[2Von]]>0,1)+IF(Tabelle10[[#This Row],[1Von]]>0,1) -> 15
A31: 3 | B31: 21 | C31: 1 | D31: 40 | E31: 41 | F31: 80 | G31: =SUM(Tabelle10[[#This Row],[1Bis]],Tabelle10[[#This Row],[2Bis]])-SUM(Tabelle10[[#This Row],[1Von]],Tabelle10[[#This Row],[2Von]])+IF(Tabelle10[[#This Row],[2Von]]>0,1)+IF(Tabelle10[[#This Row],[1Von]]>0,1) -> 80
A32: 3 | B32: 13 | C32: 1 | D32: 40 | E32: 41 | F32: 57 | G32: =SUM(Tabelle10[[#This Row],[1Bis]],Tabelle10[[#This Row],[2Bis]])-SUM(Tabelle10[[#This Row],[1Von]],Tabelle10[[#This Row],[2Von]])+IF(Tabelle10[[#This Row],[2Von]]>0,1)+IF(Tabelle10[[#This Row],[1Von]]>0,1) -> 57
A33: 3 | B33: 20 | C33: 1 | D33: 40 | E33: 41 | F33: 80 | G33: =SUM(Tabelle10[[#This Row],[1Bis]],Tabelle10[[#This Row],[2Bis]])-SUM(Tabelle10[[#This Row],[1Von]],Tabelle10[[#This Row],[2Von]])+IF(Tabelle10[[#This Row],[2Von]]>0,1)+IF(Tabelle10[[#This Row],[1Von]]>0,1) -> 80
A34: 3 | B34: 16 | C34: 1 | D34: 40 | E34: 41 | F34: 80 | G34: =SUM(Tabelle10[[#This Row],[1Bis]],Tabelle10[[#This Row],[2Bis]])-SUM(Tabelle10[[#This Row],[1Von]],Tabelle10[[#This Row],[2Von]])+IF(Tabelle10[[#This Row],[2Von]]>0,1)+IF(Tabelle10[[#This Row],[1Von]]>0,1) -> 80
A35: 3 | B35: 23 | C35: 1 | D35: 40 | E35: 41 | F35: 80 | G35: =SUM(Tabelle10[[#This Row],[1Bis]],Tabelle10[[#This Row],[2Bis]])-SUM(Tabelle10[[#This Row],[1Von]],Tabelle10[[#This Row],[2Von]])+IF(Tabelle10[[#This Row],[2Von]]>0,1)+IF(Tabelle10[[#This Row],[1Von]]>0,1) -> 80
A36: 3 | B36: 26 | C36: 1 | D36: 40 | E36: 41 | F36: 80 | G36: =SUM(Tabelle10[[#This Row],[1Bis]],Tabelle10[[#This Row],[2Bis]])-SUM(Tabelle10[[#This Row],[1Von]],Tabelle10[[#This Row],[2Von]])+IF(Tabelle10[[#This Row],[2Von]]>0,1)+IF(Tabelle10[[#This Row],[1Von]]>0,1) -> 80
A37: 3 | B37: 6 | C37: 1 | D37: 40 | E37: 41 | F37: 66 | G37: =SUM(Tabelle10[[#This Row],[1Bis]],Tabelle10[[#This Row],[2Bis]])-SUM(Tabelle10[[#This Row],[1Von]],Tabelle10[[#This Row],[2Von]])+IF(Tabelle10[[#This Row],[2Von]]>0,1)+IF(Tabelle10[[#This Row],[1Von]]>0,1) -> 66
A38: 3 | B38: 7 | C38: 1 | D38: 40 | E38: 41 | F38: 80 | G38: =SUM(Tabelle10[[#This Row],[1Bis]],Tabelle10[[#This Row],[2Bis]])-SUM(Tabelle10[[#This Row],[1Von]],Tabelle10[[#This Row],[2Von]])+IF(Tabelle10[[#This Row],[2Von]]>0,1)+IF(Tabelle10[[#This Row],[1Von]]>0,1) -> 80
A39: 3 | B39: 8 | C39: 1 | D39: 40 | E39: 41 | F39: 48 | G39: =SUM(Tabelle10[[#This Row],[1Bis]],Tabelle10[[#This Row],[2Bis]])-SUM(Tabelle10[[#This Row],[1Von]],Tabelle10[[#This Row],[2Von]])+IF(Tabelle10[[#This Row],[2Von]]>0,1)+IF(Tabelle10[[#This Row],[1Von]]>0,1) -> 48
A40: 3 | B40: 27 | C40: 1 | D40: 40 | E40: 41 | F40: 57 | G40: =SUM(Tabelle10[[#This Row],[1Bis]],Tabelle10[[#This Row],[2Bis]])-SUM(Tabelle10[[#This Row],[1Von]],Tabelle10[[#This Row],[2Von]])+IF(Tabelle10[[#This Row],[2Von]]>0,1)+IF(Tabelle10[[#This Row],[1Von]]>0,1) -> 57
...

Sheet Rote Karten
A1: SID | B1: Min | C1: HZ | D1: Team | E1: TNr
A2: 3 | B2: 53 | C2: 2 | D2: TSV
A3: 5 | B3: 26 | C3: 1 | D3: FCM
A4: 9 | B4: 41 | C4: 1 | D4: FCN | E4: 27

Sheet Abschlüsse
A1: SID | B1: TID | C1: HG | D1: GID | E1: AbNr | F1: Min | G1: HZ | H1: PR | I1: SpSt | J1: GS | K1: AP | L1: Ergeb | M1: Phase | N1: VorT | O1: VNr | P1: 2VNr | Q1: 3VNr | R1: 4VNr | S1: 5VNr | T1: 6VNr | U1: 7VNr | V1: 8VNr | W1: 9VNr | X1: 10VNr | Y1: 11VNr | Z1: 12VNr | AA1: (VFB) | AB1: KörT | AC1: TrefH | AD1: KörR | AE1: SNr | AF1: xFe | AG1: yFe | AH1: DisT | AI1: WinT | AJ1: TWA | AK1: xTW | AL1: yTW | AM1: TWD | AN1: StrA | AO1: xStr | AP1: yStr | AQ1: DSD | AR1: BloA | AS1: xBlo | AT1: yBlo | AU1: DBD
A2: 1 | B2: FCN | C2: =IF($A2="","",IF(VLOOKUP($A2,Spiele!$A$2:$D$16,3,FALSE)=$B2,"H","G")) -> H | D2: =IF($B2="","",IF(VLOOKUP($A2,Spiele!$A$2:$F$16,3,FALSE)=$B2,VLOOKUP($A2,Spiele!$A$2:$F$16,4,FALSE),VLOOKUP($A2,Spiele!$A$2:$F$16,3,FALSE))) -> GWD | E2: =IF(Abschlüsse[[#This Row],[Ergeb]]="ET",0,COUNTIFS($A$2:$A2,$A2,$B$2:$B2,$B2,$L$2:$L2,"<>ET")) -> 1 | F2: 3 | G2: 1 | H2: =COUNTIFS('Rote Karten'!$A$2:$A$4,$A2,'Rote Karten'!$D$2:$D$4,"<>"&$B2,'Rote Karten'!$B$2:$B$4,"<"&$F2,'Rote Karten'!$C$2:$C$4,"<="&$G2)-COUNTIFS('Rote Karten'!$A$2:$A$4,$A2,'Rote Karten'!$D$2:$D$4,$B2,'Rote Karten'!$B$2:$B$4,"<"&$F2,'Rote Karten'!$C$2:$C$4,"<="&$G2) -> 0 | I2: =IF(OR($L2="Tor",$L2="ET"),_xlfn.IFNA(IF(VLOOKUP($A2,Spiele!$A$2:$C$16,3,FALSE)=$B2,COUNTIFS($L$2:$L2,"Tor",$B$2:$B2,$B2,$A$2:$A2,$A2)+COUNTIFS($L$2:$L2,"ET",$B$2:$B2,$B2,$A$2:$A2,$A2)&":"&COUNTIFS($L$2:$L2,"Tor",$B$2:$B2,"<>"&$B2,$A$2:$A2,$A2)+COUNTIFS($L$2:$L2,"ET",$B$2:$B2,"<>"&$B2,$A$2:$A2,$A2),COUNTIFS($L$2:$L2,"Tor",$B$2:$B2,"<>"&$B2,$A$2:$A2,$A2)+COUNTIFS($L$2:$L2,"ET",$B$2:$B2,"<>"&$B2,$A$2:$A2,$A2)&":"&COUNTIFS($L$2:$L2,"Tor",$B$2:$B2,$B2,$A$2:$A2,$A2)+COUNTIFS($L$2:$L2,"ET",$B$2:$B2,$B2,$A$2:$A2,$A2)),""),"") | J2: =_xlfn.IFNA(IF(VLOOKUP($A2,Spiele!$A$2:$D$16,3,FALSE)=$B2,(COUNTIFS($L$1:$L1,"Tor",$B$1:$B1,$B2,$A$1:$A1,$A2)+COUNTIFS($L$1:$L1,"ET",$B$1:$B1,$B2,$A$1:$A1,$A2))-(COUNTIFS($L$1:$L1,"Tor",$B$1:$B1,"<>"&$B2,$A$1:$A1,$A2)+COUNTIFS($L$1:$L1,"ET",$B$1:$B1,"<>"&$B2,$A$1:$A1,$A2)),(COUNTIFS($L$1:$L1,"Tor",$B$1:$B1,$B2,$A$1:$A1,$A2)+COUNTIFS($L$1:$L1,"ET",$B$1:$B1,$B2,$A$1:$A1,$A2))-(COUNTIFS($L$1:$L1,"Tor",$B$1:$B1,"<>"&$B2,$A$1:$A1,$A2)+COUNTIFS($L$1:$L1,"ET",$B$1:$B1,"<>"&$B2,$A$1:$A1,$A2))),"") -> 0 | K2: 1 | L2: Block | M2: nFS | N2: AP | AA2: As | AB2: R | AC2: Son | AD2: BzT | AE2: 11 | AF2: 5 | AG2: 18.5 | AH2: =IF($L2="ET","",IF($AF2>3.66,SQRT($AG2^2+($AF2-(7.32/2))^2),IF($AF2<-3.66,SQRT($AG2^2+($AF2+(7.32/2))^2),$AG2))) -> 18.548466 | AI2: =IF($L2="ET","",IF(DEGREES(ATAN((7.32*$AG2)/($AG2^2+$AF2^2-(7.32/2)^2)))<=0,180+DEGREES(ATAN((7.32*$AG2)/($AG2^2+$AF2^2-(7.32/2)^2))),DEGREES(ATAN((7.32*$AG2)/($AG2^2+$AF2^2-(7.32/2)^2))))) -> 20.941837 | AJ2: SB | AK2: 1 | AL2: 2 | AM2: =IF(Abschlüsse[[#This Row],[Ergeb]]="ET","",SQRT(($AF2-$AK2)^2+($AG2-$AL2)^2)) -> 16.977927 | AN2: 0 | AQ2: =IF(AN2=0,"",SQRT(($AF2-$AO2)^2+($AG2-$AP2)^2)) | AR2: 3 | AS2: 4.5 | AT2: 17 | AU2: =IF(AR2=0,"",SQRT(($AF2-$AS2)^2+($AG2-$AT2)^2)) -> 1.5811388
A3: 1 | B3: FCN | C3: =IF($A3="","",IF(VLOOKUP($A3,Spiele!$A$2:$D$16,3,FALSE)=$B3,"H","G")) -> H | D3: =IF($B3="","",IF(VLOOKUP($A3,Spiele!$A$2:$F$16,3,FALSE)=$B3,VLOOKUP($A3,Spiele!$A$2:$F$16,4,FALSE),VLOOKUP($A3,Spiele!$A$2:$F$16,3,FALSE))) -> GWD | E3: =IF(Abschlüsse[[#This Row],[Ergeb]]="ET",0,COUNTIFS($A$2:$A3,$A3,$B$2:$B3,$B3,$L$2:$L3,"<>ET")) -> 2 | F3: 6 | G3: 1 | H3: =COUNTIFS('Rote Karten'!$A$2:$A$4,$A3,'Rote Karten'!$D$2:$D$4,"<>"&$B3,'Rote Karten'!$B$2:$B$4,"<"&$F3,'Rote Karten'!$C$2:$C$4,"<="&$G3)-COUNTIFS('Rote Karten'!$A$2:$A$4,$A3,'Rote Karten'!$D$2:$D$4,$B3,'Rote Karten'!$B$2:$B$4,"<"&$F3,'Rote Karten'!$C$2:$C$4,"<="&$G3) -> 0 | I3: =IF(OR($L3="Tor",$L3="ET"),_xlfn.IFNA(IF(VLOOKUP($A3,Spiele!$A$2:$C$16,3,FALSE)=$B3,COUNTIFS($L$2:$L3,"Tor",$B$2:$B3,$B3,$A$2:$A3,$A3)+COUNTIFS($L$2:$L3,"ET",$B$2:$B3,$B3,$A$2:$A3,$A3)&":"&COUNTIFS($L$2:$L3,"Tor",$B$2:$B3,"<>"&$B3,$A$2:$A3,$A3)+COUNTIFS($L$2:$L3,"ET",$B$2:$B3,"<>"&$B3,$A$2:$A3,$A3),COUNTIFS($L$2:$L3,"Tor",$B$2:$B3,"<>"&$B3,$A$2:$A3,$A3)+COUNTIFS($L$2:$L3,"ET",$B$2:$B3,"<>"&$B3,$A$2:$A3,$A3)&":"&COUNTIFS($L$2:$L3,"Tor",$B$2:$B3,$B3,$A$2:$A3,$A3)+COUNTIFS($L$2:$L3,"ET",$B$2:$B3,$B3,$A$2:$A3,$A3)),""),"") -> 1:0 | J3: =_xlfn.IFNA(IF(VLOOKUP($A3,Spiele!$A$2:$D$16,3,FALSE)=$B3,(COUNTIFS($L$1:$L2,"Tor",$B$1:$B2,$B3,$A$1:$A2,$A3)+COUNTIFS($L$1:$L2,"ET",$B$1:$B2,$B3,$A$1:$A2,$A3))-(COUNTIFS($L$1:$L2,"Tor",$B$1:$B2,"<>"&$B3,$A$1:$A2,$A3)+COUNTIFS($L$1:$L2,"ET",$B$1:$B2,"<>"&$B3,$A$1:$A2,$A3)),(COUNTIFS($L$1:$L2,"Tor",$B$1:$B2,$B3,$A$1:$A2,$A3)+COUNTIFS($L$1:$L2,"ET",$B$1:$B2,$B3,$A$1:$A2,$A3))-(COUNTIFS($L$1:$L2,"Tor",$B$1:$B2,"<>"&$B3,$A$1:$A2,$A3)+COUNTIFS($L$1:$L2,"ET",$B$1:$B2,"<>"&$B3,$A$1:$A2,$A3))),"") -> 0 | K3: 2 | L3: Tor | M3: EB | N3: TB | O3: 20 | P3: 26 | Q3: 23 | R3: 20 | AA3: vB | AB3: L | AC3: Fuß | AD3: BzT | AE3: 9 | AF3: -6.5 | AG3: 8.5 | AH3: =IF($L3="ET","",IF($AF3>3.66,SQRT($AG3^2+($AF3-(7.32/2))^2),IF($AF3<-3.66,SQRT($AG3^2+($AF3+(7.32/2))^2),$AG3))) -> 8.9618971 | AI3: =IF($L3="ET","",IF(DEGREES(ATAN((7.32*$AG3)/($AG3^2+$AF3^2-(7.32/2)^2)))<=0,180+DEGREES(ATAN((7.32*$AG3)/($AG3^2+$AF3^2-(7.32/2)^2))),DEGREES(ATAN((7.32*$AG3)/($AG3^2+$AF3^2-(7.32/2)^2))))) -> 31.608286 | AJ3: SB | AK3: -3.5 | AL3: 4.5 | AM3: =IF(Abschlüsse[[#This Row],[Ergeb]]="ET","",SQRT(($AF3-$AK3)^2+($AG3-$AL3)^2)) -> 5 | AN3: 2 | AO3: -6 | AP3: 8.5 | AQ3: =IF(AN3=0,"",SQRT(($AF3-$AO3)^2+($AG3-$AP3)^2)) -> 0.5 | AR3: 0 | AU3: =IF(AR3=0,"",SQRT(($AF3-$AS3)^2+($AG3-$AT3)^2))
A4: 1 | B4: FCN | C4: =IF($A4="","",IF(VLOOKUP($A4,Spiele!$A$2:$D$16,3,FALSE)=$B4,"H","G")) -> H | D4: =IF($B4="","",IF(VLOOKUP($A4,Spiele!$A$2:$F$16,3,FALSE)=$B4,VLOOKUP($A4,Spiele!$A$2:$F$16,4,FALSE),VLOOKUP($A4,Spiele!$A$2:$F$16,3,FALSE))) -> GWD | E4: =IF(Abschlüsse[[#This Row],[Ergeb]]="ET",0,COUNTIFS($A$2:$A4,$A4,$B$2:$B4,$B4,$L$2:$L4,"<>ET")) -> 3 | F4: 8 | G4: 1 | H4: =COUNTIFS('Rote Karten'!$A$2:$A$4,$A4,'Rote Karten'!$D$2:$D$4,"<>"&$B4,'Rote Karten'!$B$2:$B$4,"<"&$F4,'Rote Karten'!$C$2:$C$4,"<="&$G4)-COUNTIFS('Rote Karten'!$A$2:$A$4,$A4,'Rote Karten'!$D$2:$D$4,$B4,'Rote Karten'!$B$2:$B$4,"<"&$F4,'Rote Karten'!$C$2:$C$4,"<="&$G4) -> 0 | I4: =IF(OR($L4="Tor",$L4="ET"),_xlfn.IFNA(IF(VLOOKUP($A4,Spiele!$A$2:$C$16,3,FALSE)=$B4,COUNTIFS($L$2:$L4,"Tor",$B$2:$B4,$B4,$A$2:$A4,$A4)+COUNTIFS($L$2:$L4,"ET",$B$2:$B4,$B4,$A$2:$A4,$A4)&":"&COUNTIFS($L$2:$L4,"Tor",$B$2:$B4,"<>"&$B4,$A$2:$A4,$A4)+COUNTIFS($L$2:$L4,"ET",$B$2:$B4,"<>"&$B4,$A$2:$A4,$A4),COUNTIFS($L$2:$L4,"Tor",$B$2:$B4,"<>"&$B4,$A$2:$A4,$A4)+COUNTIFS($L$2:$L4,"ET",$B$2:$B4,"<>"&$B4,$A$2:$A4,$A4)&":"&COUNTIFS($L$2:$L4,"Tor",$B$2:$B4,$B4,$A$2:$A4,$A4)+COUNTIFS($L$2:$L4,"ET",$B$2:$B4,$B4,$A$2:$A4,$A4)),""),"") | J4: =_xlfn.IFNA(IF(VLOOKUP($A4,Spiele!$A$2:$D$16,3,FALSE)=$B4,(COUNTIFS($L$1:$L3,"Tor",$B$1:$B3,$B4,$A$1:$A3,$A4)+COUNTIFS($L$1:$L3,"ET",$B$1:$B3,$B4,$A$1:$A3,$A4))-(COUNTIFS($L$1:$L3,"Tor",$B$1:$B3,"<>"&$B4,$A$1:$A3,$A4)+COUNTIFS($L$1:$L3,"ET",$B$1:$B3,"<>"&$B4,$A$1:$A3,$A4)),(COUNTIFS($L$1:$L3,"Tor",$B$1:$B3,$B4,$A$1:$A3,$A4)+COUNTIFS($L$1:$L3,"ET",$B$1:$B3,$B4,$A$1:$A3,$A4))-(COUNTIFS($L$1:$L3,"Tor",$B$1:$B3,"<>"&$B4,$A$1:$A3,$A4)+COUNTIFS($L$1:$L3,"ET",$B$1:$B3,"<>"&$B4,$A$1:$A3,$A4))),"") -> 1 | K4: 3 | L4: Block | M4: EB | N4: RP | O4: 20 | P4: 26 | Q4: 6 | R4: 23 | S4: 8 | AA4: nd | AB4: R | AC4: Fuß | AD4: adD | AE4: 27 | AF4: -17 | AG4: 18.5 | AH4: =IF($L4="ET","",IF($AF4>3.66,SQRT($AG4^2+($AF4-(7.32/2))^2),IF($AF4<-3.66,SQRT($AG4^2+($AF4+(7.32/2))^2),$AG4))) -> 22.808016 | AI4: =IF($L4="ET","",IF(DEGREES(ATAN((7.32*$AG4)/($AG4^2+$AF4^2-(7.32/2)^2)))<=0,180+DEGREES(ATAN((7.32*$AG4)/($AG4^2+$AF4^2-(7.32/2)^2))),DEGREES(ATAN((7.32*$AG4)/($AG4^2+$AF4^2-(7.32/2)^2))))) -> 12.36248 | AJ4: SB | AK4: -1.5 | AL4: 2.5 | AM4: =IF(Abschlüsse[[#This Row],[Ergeb]]="ET","",SQRT(($AF4-$AK4)^2+($AG4-$AL4)^2)) -> 22.276669 | AN4: 1 | AO4: -18 | AP4: 20 | AQ4: =IF(AN4=0,"",SQRT(($AF4-$AO4)^2+($AG4-$AP4)^2)) -> 1.8027756 | AR4: 3 | AS4: -15 | AT4: 16.5 | AU4: =IF(AR4=0,"",SQRT(($AF4-$AS4)^2+($AG4-$AT4)^2)) -> 2.8284271
A5: 1 | B5: GWD | C5: =IF($A5="","",IF(VLOOKUP($A5,Spiele!$A$2:$D$16,3,FALSE)=$B5,"H","G")) -> G | D5: =IF($B5="","",IF(VLOOKUP($A5,Spiele!$A$2:$F$16,3,FALSE)=$B5,VLOOKUP($A5,Spiele!$A$2:$F$16,4,FALSE),VLOOKUP($A5,Spiele!$A$2:$F$16,3,FALSE))) -> FCN | E5: =IF(Abschlüsse[[#This Row],[Ergeb]]="ET",0,COUNTIFS($A$2:$A5,$A5,$B$2:$B5,$B5,$L$2:$L5,"<>ET")) -> 1 | F5: 11 | G5: 1 | H5: =COUNTIFS('Rote Karten'!$A$2:$A$4,$A5,'Rote Karten'!$D$2:$D$4,"<>"&$B5,'Rote Karten'!$B$2:$B$4,"<"&$F5,'Rote Karten'!$C$2:$C$4,"<="&$G5)-COUNTIFS('Rote Karten'!$A$2:$A$4,$A5,'Rote Karten'!$D$2:$D$4,$B5,'Rote Karten'!$B$2:$B$4,"<"&$F5,'Rote Karten'!$C$2:$C$4,"<="&$G5) -> 0 | I5: =IF(OR($L5="Tor",$L5="ET"),_xlfn.IFNA(IF(VLOOKUP($A5,Spiele!$A$2:$C$16,3,FALSE)=$B5,COUNTIFS($L$2:$L5,"Tor",$B$2:$B5,$B5,$A$2:$A5,$A5)+COUNTIFS($L$2:$L5,"ET",$B$2:$B5,$B5,$A$2:$A5,$A5)&":"&COUNTIFS($L$2:$L5,"Tor",$B$2:$B5,"<>"&$B5,$A$2:$A5,$A5)+COUNTIFS($L$2:$L5,"ET",$B$2:$B5,"<>"&$B5,$A$2:$A5,$A5),COUNTIFS($L$2:$L5,"Tor",$B$2:$B5,"<>"&$B5,$A$2:$A5,$A5)+COUNTIFS($L$2:$L5,"ET",$B$2:$B5,"<>"&$B5,$A$2:$A5,$A5)&":"&COUNTIFS($L$2:$L5,"Tor",$B$2:$B5,$B5,$A$2:$A5,$A5)+COUNTIFS($L$2:$L5,"ET",$B$2:$B5,$B5,$A$2:$A5,$A5)),""),"") | J5: =_xlfn.IFNA(IF(VLOOKUP($A5,Spiele!$A$2:$D$16,3,FALSE)=$B5,(COUNTIFS($L$1:$L4,"Tor",$B$1:$B4,$B5,$A$1:$A4,$A5)+COUNTIFS($L$1:$L4,"ET",$B$1:$B4,$B5,$A$1:$A4,$A5))-(COUNTIFS($L$1:$L4,"Tor",$B$1:$B4,"<>"&$B5,$A$1:$A4,$A5)+COUNTIFS($L$1:$L4,"ET",$B$1:$B4,"<>"&$B5,$A$1:$A4,$A5)),(COUNTIFS($L$1:$L4,"Tor",$B$1:$B4,$B5,$A$1:$A4,$A5)+COUNTIFS($L$1:$L4,"ET",$B$1:$B4,$B5,$A$1:$A4,$A5))-(COUNTIFS($L$1:$L4,"Tor",$B$1:$B4,"<>"&$B5,$A$1:$A4,$A5)+COUNTIFS($L$1:$L4,"ET",$B$1:$B4,"<>"&$B5,$A$1:$A4,$A5))),"") -> -1 | K5: 4 | L5: Vorbei | M5: nFS | N5: AP | AA5: nd | AB5: R | AC5: Son | AD5: BzT | AF5: 2 | AG5: 26 | AH5: =IF($L5="ET","",IF($AF5>3.66,SQRT($AG5^2+($AF5-(7.32/2))^2),IF($AF5<-3.66,SQRT($AG5^2+($AF5+(7.32/2))^2),$AG5))) -> 26 | AI5: =IF($L5="ET","",IF(DEGREES(ATAN((7.32*$AG5)/($AG5^2+$AF5^2-(7.32/2)^2)))<=0,180+DEGREES(ATAN((7.32*$AG5)/($AG5^2+$AF5^2-(7.32/2)^2))),DEGREES(ATAN((7.32*$AG5)/($AG5^2+$AF5^2-(7.32/2)^2))))) -> 15.934397 | AJ5: SB | AK5: 2 | AL5: 5 | AM5: =IF(Abschlüsse[[#This Row],[Ergeb]]="ET","",SQRT(($AF5-$AK5)^2+($AG5-$AL5)^2)) -> 21 | AN5: 0 | AQ5: =IF(AN5=0,"",SQRT(($AF5-$AO5)^2+($AG5-$AP5)^2)) | AR5: 2 | AS5: 1.5 | AT5: 16 | AU5: =IF(AR5=0,"",SQRT(($AF5-$AS5)^2+($AG5-$AT5)^2)) -> 10.012492
A6: 1 | B6: FCN | C6: =IF($A6="","",IF(VLOOKUP($A6,Spiele!$A$2:$D$16,3,FALSE)=$B6,"H","G")) -> H | D6: =IF($B6="","",IF(VLOOKUP($A6,Spiele!$A$2:$F$16,3,FALSE)=$B6,VLOOKUP($A6,Spiele!$A$2:$F$16,4,FALSE),VLOOKUP($A6,Spiele!$A$2:$F$16,3,FALSE))) -> GWD | E6: =IF(Abschlüsse[[#This Row],[Ergeb]]="ET",0,COUNTIFS($A$2:$A6,$A6,$B$2:$B6,$B6,$L$2:$L6,"<>ET")) -> 4 | F6: 14 | G6: 1 | H6: =COUNTIFS('Rote Karten'!$A$2:$A$4,$A6,'Rote Karten'!$D$2:$D$4,"<>"&$B6,'Rote Karten'!$B$2:$B$4,"<"&$F6,'Rote Karten'!$C$2:$C$4,"<="&$G6)-COUNTIFS('Rote Karten'!$A$2:$A$4,$A6,'Rote Karten'!$D$2:$D$4,$B6,'Rote Karten'!$B$2:$B$4,"<"&$F6,'Rote Karten'!$C$2:$C$4,"<="&$G6) -> 0 | I6: =IF(OR($L6="Tor",$L6="ET"),_xlfn.IFNA(IF(VLOOKUP($A6,Spiele!$A$2:$C$16,3,FALSE)=$B6,COUNTIFS($L$2:$L6,"Tor",$B$2:$B6,$B6,$A$2:$A6,$A6)+COUNTIFS($L$2:$L6,"ET",$B$2:$B6,$B6,$A$2:$A6,$A6)&":"&COUNTIFS($L$2:$L6,"Tor",$B$2:$B6,"<>"&$B6,$A$2:$A6,$A6)+COUNTIFS($L$2:$L6,"ET",$B$2:$B6,"<>"&$B6,$A$2:$A6,$A6),COUNTIFS($L$2:$L6,"Tor",$B$2:$B6,"<>"&$B6,$A$2:$A6,$A6)+COUNTIFS($L$2:$L6,"ET",$B$2:$B6,"<>"&$B6,$A$2:$A6,$A6)&":"&COUNTIFS($L$2:$L6,"Tor",$B$2:$B6,$B6,$A$2:$A6,$A6)+COUNTIFS($L$2:$L6,"ET",$B$2:$B6,$B6,$A$2:$A6,$A6)),""),"") | J6: =_xlfn.IFNA(IF(VLOOKUP($A6,Spiele!$A$2:$D$16,3,FALSE)=$B6,(COUNTIFS($L$1:$L5,"Tor",$B$1:$B5,$B6,$A$1:$A5,$A6)+COUNTIFS($L$1:$L5,"ET",$B$1:$B5,$B6,$A$1:$A5,$A6))-(COUNTIFS($L$1:$L5,"Tor",$B$1:$B5,"<>"&$B6,$A$1:$A5,$A6)+COUNTIFS($L$1:$L5,"ET",$B$1:$B5,"<>"&$B6,$A$1:$A5,$A6)),(COUNTIFS($L$1:$L5,"Tor",$B$1:$B5,$B6,$A$1:$A5,$A6)+COUNTIFS($L$1:$L5,"ET",$B$1:$B5,$B6,$A$1:$A5,$A6))-(COUNTIFS($L$1:$L5,"Tor",$B$1:$B5,"<>"&$B6,$A$1:$A5,$A6)+COUNTIFS($L$1:$L5,"ET",$B$1:$B5,"<>"&$B6,$A$1:$A5,$A6))),"") -> 1 | K6: 5 | L6: Save | M6: EB | N6: SP | O6: 8 | P6: 20 | Q6: 1 | R6: 26 | S6: 23 | T6: 6 | U6: 8 | AA6: nd | AB6: R | AC6: Fuß | AD6: BzT | AE6: 9 | AF6: -1 | AG6: 15 | AH6: =IF($L6="ET","",IF($AF6>3.66,SQRT($AG6^2+($AF6-(7.32/2))^2),IF($AF6<-3.66,SQRT($AG6^2+($AF6+(7.32/2))^2),$AG6))) -> 15 | AI6: =IF($L6="ET","",IF(DEGREES(ATAN((7.32*$AG6)/($AG6^2+$AF6^2-(7.32/2)^2)))<=0,180+DEGREES(ATAN((7.32*$AG6)/($AG6^2+$AF6^2-(7.32/2)^2))),DEGREES(ATAN((7.32*$AG6)/($AG6^2+$AF6^2-(7.32/2)^2))))) -> 27.314189 | AJ6: SB | AK6: -0.5 | AL6: 7 | AM6: =IF(Abschlüsse[[#This Row],[Ergeb]]="ET","",SQRT(($AF6-$AK6)^2+($AG6-$AL6)^2)) -> 8.0156098 | AN6: 1 | AO6: -4 | AP6: 14.5 | AQ6: =IF(AN6=0,"",SQRT(($AF6-$AO6)^2+($AG6-$AP6)^2)) -> 3.0413813 | AR6: 0 | AU6: =IF(AR6=0,"",SQRT(($AF6-$AS6)^2+($AG6-$AT6)^2))
A7: 1 | B7: FCN | C7: =IF($A7="","",IF(VLOOKUP($A7,Spiele!$A$2:$D$16,3,FALSE)=$B7,"H","G")) -> H | D7: =IF($B7="","",IF(VLOOKUP($A7,Spiele!$A$2:$F$16,3,FALSE)=$B7,VLOOKUP($A7,Spiele!$A$2:$F$16,4,FALSE),VLOOKUP($A7,Spiele!$A$2:$F$16,3,FALSE))) -> GWD | E7: =IF(Abschlüsse[[#This Row],[Ergeb]]="ET",0,COUNTIFS($A$2:$A7,$A7,$B$2:$B7,$B7,$L$2:$L7,"<>ET")) -> 5 | F7: 16 | G7: 1 | H7: =COUNTIFS('Rote Karten'!$A$2:$A$4,$A7,'Rote Karten'!$D$2:$D$4,"<>"&$B7,'Rote Karten'!$B$2:$B$4,"<"&$F7,'Rote Karten'!$C$2:$C$4,"<="&$G7)-COUNTIFS('Rote Karten'!$A$2:$A$4,$A7,'Rote Karten'!$D$2:$D$4,$B7,'Rote Karten'!$B$2:$B$4,"<"&$F7,'Rote Karten'!$C$2:$C$4,"<="&$G7) -> 0 | I7: =IF(OR($L7="Tor",$L7="ET"),_xlfn.IFNA(IF(VLOOKUP($A7,Spiele!$A$2:$C$16,3,FALSE)=$B7,COUNTIFS($L$2:$L7,"Tor",$B$2:$B7,$B7,$A$2:$A7,$A7)+COUNTIFS($L$2:$L7,"ET",$B$2:$B7,$B7,$A$2:$A7,$A7)&":"&COUNTIFS($L$2:$L7,"Tor",$B$2:$B7,"<>"&$B7,$A$2:$A7,$A7)+COUNTIFS($L$2:$L7,"ET",$B$2:$B7,"<>"&$B7,$A$2:$A7,$A7),COUNTIFS($L$2:$L7,"Tor",$B$2:$B7,"<>"&$B7,$A$2:$A7,$A7)+COUNTIFS($L$2:$L7,"ET",$B$2:$B7,"<>"&$B7,$A$2:$A7,$A7)&":"&COUNTIFS($L$2:$L7,"Tor",$B$2:$B7,$B7,$A$2:$A7,$A7)+COUNTIFS($L$2:$L7,"ET",$B$2:$B7,$B7,$A$2:$A7,$A7)),""),"") -> 2:0 | J7: =_xlfn.IFNA(IF(VLOOKUP($A7,Spiele!$A$2:$D$16,3,FALSE)=$B7,(COUNTIFS($L$1:$L6,"Tor",$B$1:$B6,$B7,$A$1:$A6,$A7)+COUNTIFS($L$1:$L6,"ET",$B$1:$B6,$B7,$A$1:$A6,$A7))-(COUNTIFS($L$1:$L6,"Tor",$B$1:$B6,"<>"&$B7,$A$1:$A6,$A7)+COUNTIFS($L$1:$L6,"ET",$B$1:$B6,"<>"&$B7,$A$1:$A6,$A7)),(COUNTIFS($L$1:$L6,"Tor",$B$1:$B6,$B7,$A$1:$A6,$A7)+COUNTIFS($L$1:$L6,"ET",$B$1:$B6,$B7,$A$1:$A6,$A7))-(COUNTIFS($L$1:$L6,"Tor",$B$1:$B6,"<>"&$B7,$A$1:$A6,$A7)+COUNTIFS($L$1:$L6,"ET",$B$1:$B6,"<>"&$B7,$A$1:$A6,$A7))),"") -> 1 | K7: 6 | L7: Tor | M7: EB | N7: F | O7: 8 | P7: 26 | Q7: 23 | R7: 6 | S7: 20 | T7: 13 | AA7: adL | AB7: R | AC7: Son | AD7: BzT | AE7: 7 | AF7: 0.5 | AG7: 6.5 | AH7: =IF($L7="ET","",IF($AF7>3.66,SQRT($AG7^2+($AF7-(7.32/2))^2),IF($AF7<-3.66,SQRT($AG7^2+($AF7+(7.32/2))^2),$AG7))) -> 6.5 | AI7: =IF($L7="ET","",IF(DEGREES(ATAN((7.32*$AG7)/($AG7^2+$AF7^2-(7.32/2)^2)))<=0,180+DEGREES(ATAN((7.32*$AG7)/($AG7^2+$AF7^2-(7.32/2)^2))),DEGREES(ATAN((7.32*$AG7)/($AG7^2+$AF7^2-(7.32/2)^2))))) -> 58.546125 | AJ7: SB | AK7: 0 | AL7: 2 | AM7: =IF(Abschlüsse[[#This Row],[Ergeb]]="ET","",SQRT(($AF7-$AK7)^2+($AG7-$AL7)^2)) -> 4.5276926 | AN7: 0 | AQ7: =IF(AN7=0,"",SQRT(($AF7-$AO7)^2+($AG7-$AP7)^2)) | AR7: 0 | AU7: =IF(AR7=0,"",SQRT(($AF7-$AS7)^2+($AG7-$AT7)^2))
A8: 1 | B8: GWD | C8: =IF($A8="","",IF(VLOOKUP($A8,Spiele!$A$2:$D$16,3,FALSE)=$B8,"H","G")) -> G | D8: =IF($B8="","",IF(VLOOKUP($A8,Spiele!$A$2:$F$16,3,FALSE)=$B8,VLOOKUP($A8,Spiele!$A$2:$F$16,4,FALSE),VLOOKUP($A8,Spiele!$A$2:$F$16,3,FALSE))) -> FCN | E8: =IF(Abschlüsse[[#This Row],[Ergeb]]="ET",0,COUNTIFS($A$2:$A8,$A8,$B$2:$B8,$B8,$L$2:$L8,"<>ET")) -> 2 | F8: 18 | G8: 1 | H8: =COUNTIFS('Rote Karten'!$A$2:$A$4,$A8,'Rote Karten'!$D$2:$D$4,"<>"&$B8,'Rote Karten'!$B$2:$B$4,"<"&$F8,'Rote Karten'!$C$2:$C$4,"<="&$G8)-COUNTIFS('Rote Karten'!$A$2:$A$4,$A8,'Rote Karten'!$D$2:$D$4,$B8,'Rote Karten'!$B$2:$B$4,"<"&$F8,'Rote Karten'!$C$2:$C$4,"<="&$G8) -> 0 | I8: =IF(OR($L8="Tor",$L8="ET"),_xlfn.IFNA(IF(VLOOKUP($A8,Spiele!$A$2:$C$16,3,FALSE)=$B8,COUNTIFS($L$2:$L8,"Tor",$B$2:$B8,$B8,$A$2:$A8,$A8)+COUNTIFS($L$2:$L8,"ET",$B$2:$B8,$B8,$A$2:$A8,$A8)&":"&COUNTIFS($L$2:$L8,"Tor",$B$2:$B8,"<>"&$B8,$A$2:$A8,$A8)+COUNTIFS($L$2:$L8,"ET",$B$2:$B8,"<>"&$B8,$A$2:$A8,$A8),COUNTIFS($L$2:$L8,"Tor",$B$2:$B8,"<>"&$B8,$A$2:$A8,$A8)+COUNTIFS($L$2:$L8,"ET",$B$2:$B8,"<>"&$B8,$A$2:$A8,$A8)&":"&COUNTIFS($L$2:$L8,"Tor",$B$2:$B8,$B8,$A$2:$A8,$A8)+COUNTIFS($L$2:$L8,"ET",$B$2:$B8,$B8,$A$2:$A8,$A8)),""),"") | J8: =_xlfn.IFNA(IF(VLOOKUP($A8,Spiele!$A$2:$D$16,3,FALSE)=$B8,(COUNTIFS($L$1:$L7,"Tor",$B$1:$B7,$B8,$A$1:$A7,$A8)+COUNTIFS($L$1:$L7,"ET",$B$1:$B7,$B8,$A$1:$A7,$A8))-(COUNTIFS($L$1:$L7,"Tor",$B$1:$B7,"<>"&$B8,$A$1:$A7,$A8)+COUNTIFS($L$1:$L7,"ET",$B$1:$B7,"<>"&$B8,$A$1:$A7,$A8)),(COUNTIFS($L$1:$L7,"Tor",$B$1:$B7,$B8,$A$1:$A7,$A8)+COUNTIFS($L$1:$L7,"ET",$B$1:$B7,$B8,$A$1:$A7,$A8))-(COUNTIFS($L$1:$L7,"Tor",$B$1:$B7,"<>"&$B8,$A$1:$A7,$A8)+COUNTIFS($L$1:$L7,"ET",$B$1:$B7,"<>"&$B8,$A$1:$A7,$A8))),"") -> -2 | K8: 7 | L8: Vorbei | M8: nFS | N8: ZK | AA8: nd | AB8: L | AC8: Fuß | AD8: BzT | AF8: -14.5 | AG8: 23.5 | AH8: =IF($L8="ET","",IF($AF8>3.66,SQRT($AG8^2+($AF8-(7.32/2))^2),IF($AF8<-3.66,SQRT($AG8^2+($AF8+(7.32/2))^2),$AG8))) -> 25.879637 | AI8: =IF($L8="ET","",IF(DEGREES(ATAN((7.32*$AG8)/($AG8^2+$AF8^2-(7.32/2)^2)))<=0,180+DEGREES(ATAN((7.32*$AG8)/($AG8^2+$AF8^2-(7.32/2)^2))),DEGREES(ATAN((7.32*$AG8)/($AG8^2+$AF8^2-(7.32/2)^2))))) -> 12.932858 | AJ8: SB | AK8: -1.5 | AL8: 1.5 | AM8: =IF(Abschlüsse[[#This Row],[Ergeb]]="ET","",SQRT(($AF8-$AK8)^2+($AG8-$AL8)^2)) -> 25.553865 | AN8: 0 | AQ8: =IF(AN8=0,"",SQRT(($AF8-$AO8)^2+($AG8-$AP8)^2)) | AR8: 1 | AS8: -10 | AT8: 17.5 | AU8: =IF(AR8=0,"",SQRT(($AF8-$AS8)^2+($AG8-$AT8)^2)) -> 7.5
A9: 1 | B9: GWD | C9: =IF($A9="","",IF(VLOOKUP($A9,Spiele!$A$2:$D$16,3,FALSE)=$B9,"H","G")) -> G | D9: =IF($B9="","",IF(VLOOKUP($A9,Spiele!$A$2:$F$16,3,FALSE)=$B9,VLOOKUP($A9,Spiele!$A$2:$F$16,4,FALSE),VLOOKUP($A9,Spiele!$A$2:$F$16,3,FALSE))) -> FCN | E9: =IF(Abschlüsse[[#This Row],[Ergeb]]="ET",0,COUNTIFS($A$2:$A9,$A9,$B$2:$B9,$B9,$L$2:$L9,"<>ET")) -> 3 | F9: 20 | G9: 1 | H9: =COUNTIFS('Rote Karten'!$A$2:$A$4,$A9,'Rote Karten'!$D$2:$D$4,"<>"&$B9,'Rote Karten'!$B$2:$B$4,"<"&$F9,'Rote Karten'!$C$2:$C$4,"<="&$G9)-COUNTIFS('Rote Karten'!$A$2:$A$4,$A9,'Rote Karten'!$D$2:$D$4,$B9,'Rote Karten'!$B$2:$B$4,"<"&$F9,'Rote Karten'!$C$2:$C$4,"<="&$G9) -> 0 | I9: =IF(OR($L9="Tor",$L9="ET"),_xlfn.IFNA(IF(VLOOKUP($A9,Spiele!$A$2:$C$16,3,FALSE)=$B9,COUNTIFS($L$2:$L9,"Tor",$B$2:$B9,$B9,$A$2:$A9,$A9)+COUNTIFS($L$2:$L9,"ET",$B$2:$B9,$B9,$A$2:$A9,$A9)&":"&COUNTIFS($L$2:$L9,"Tor",$B$2:$B9,"<>"&$B9,$A$2:$A9,$A9)+COUNTIFS($L$2:$L9,"ET",$B$2:$B9,"<>"&$B9,$A$2:$A9,$A9),COUNTIFS($L$2:$L9,"Tor",$B$2:$B9,"<>"&$B9,$A$2:$A9,$A9)+COUNTIFS($L$2:$L9,"ET",$B$2:$B9,"<>"&$B9,$A$2:$A9,$A9)&":"&COUNTIFS($L$2:$L9,"Tor",$B$2:$B9,$B9,$A$2:$A9,$A9)+COUNTIFS($L$2:$L9,"ET",$B$2:$B9,$B9,$A$2:$A9,$A9)),""),"") | J9: =_xlfn.IFNA(IF(VLOOKUP($A9,Spiele!$A$2:$D$16,3,FALSE)=$B9,(COUNTIFS($L$1:$L8,"Tor",$B$1:$B8,$B9,$A$1:$A8,$A9)+COUNTIFS($L$1:$L8,"ET",$B$1:$B8,$B9,$A$1:$A8,$A9))-(COUNTIFS($L$1:$L8,"Tor",$B$1:$B8,"<>"&$B9,$A$1:$A8,$A9)+COUNTIFS($L$1:$L8,"ET",$B$1:$B8,"<>"&$B9,$A$1:$A8,$A9)),(COUNTIFS($L$1:$L8,"Tor",$B$1:$B8,$B9,$A$1:$A8,$A9)+COUNTIFS($L$1:$L8,"ET",$B$1:$B8,$B9,$A$1:$A8,$A9))-(COUNTIFS($L$1:$L8,"Tor",$B$1:$B8,"<>"&$B9,$A$1:$A8,$A9)+COUNTIFS($L$1:$L8,"ET",$B$1:$B8,"<>"&$B9,$A$1:$A8,$A9))),"") -> -2 | K9: 8 | L9: Vorbei | M9: nEW | N9: RP | AA9: nd | AB9: R | AC9: Fuß | AD9: BzT | AF9: 7.5 | AG9: 26 | AH9: =IF($L9="ET","",IF($AF9>3.66,SQRT($AG9^2+($AF9-(7.32/2))^2),IF($AF9<-3.66,SQRT($AG9^2+($AF9+(7.32/2))^2),$AG9))) -> 26.282039 | AI9: =IF($L9="ET","",IF(DEGREES(ATAN((7.32*$AG9)/($AG9^2+$AF9^2-(7.32/2)^2)))<=0,180+DEGREES(ATAN((7.32*$AG9)/($AG9^2+$AF9^2-(7.32/2)^2))),DEGREES(ATAN((7.32*$AG9)/($AG9^2+$AF9^2-(7.32/2)^2))))) -> 14.829088 | AJ9: SB | AK9: 1.5 | AL9: 1.5 | AM9: =IF(Abschlüsse[[#This Row],[Ergeb]]="ET","",SQRT(($AF9-$AK9)^2+($AG9-$AL9)^2)) -> 25.223997 | AN9: 0 | AQ9: =IF(AN9=0,"",SQRT(($AF9-$AO9)^2+($AG9-$AP9)^2)) | AR9: 1 | AS9: 4.5 | AT9: 18 | AU9: =IF(AR9=0,"",SQRT(($AF9-$AS9)^2+($AG9-$AT9)^2)) -> 8.5440037
A10: 1 | B10: FCN | C10: =IF($A10="","",IF(VLOOKUP($A10,Spiele!$A$2:$D$16,3,FALSE)=$B10,"H","G")) -> H | D10: =IF($B10="","",IF(VLOOKUP($A10,Spiele!$A$2:$F$16,3,FALSE)=$B10,VLOOKUP($A10,Spiele!$A$2:$F$16,4,FALSE),VLOOKUP($A10,Spiele!$A$2:$F$16,3,FALSE))) -> GWD | E10: =IF(Abschlüsse[[#This Row],[Ergeb]]="ET",0,COUNTIFS($A$2:$A10,$A10,$B$2:$B10,$B10,$L$2:$L10,"<>ET")) -> 6 | F10: 21 | G10: 1 | H10: =COUNTIFS('Rote Karten'!$A$2:$A$4,$A10,'Rote Karten'!$D$2:$D$4,"<>"&$B10,'Rote Karten'!$B$2:$B$4,"<"&$F10,'Rote Karten'!$C$2:$C$4,"<="&$G10)-COUNTIFS('Rote Karten'!$A$2:$A$4,$A10,'Rote Karten'!$D$2:$D$4,$B10,'Rote Karten'!$B$2:$B$4,"<"&$F10,'Rote Karten'!$C$2:$C$4,"<="&$G10) -> 0 | I10: =IF(OR($L10="Tor",$L10="ET"),_xlfn.IFNA(IF(VLOOKUP($A10,Spiele!$A$2:$C$16,3,FALSE)=$B10,COUNTIFS($L$2:$L10,"Tor",$B$2:$B10,$B10,$A$2:$A10,$A10)+COUNTIFS($L$2:$L10,"ET",$B$2:$B10,$B10,$A$2:$A10,$A10)&":"&COUNTIFS($L$2:$L10,"Tor",$B$2:$B10,"<>"&$B10,$A$2:$A10,$A10)+COUNTIFS($L$2:$L10,"ET",$B$2:$B10,"<>"&$B10,$A$2:$A10,$A10),COUNTIFS($L$2:$L10,"Tor",$B$2:$B10,"<>"&$B10,$A$2:$A10,$A10)+COUNTIFS($L$2:$L10,"ET",$B$2:$B10,"<>"&$B10,$A$2:$A10,$A10)&":"&COUNTIFS($L$2:$L10,"Tor",$B$2:$B10,$B10,$A$2:$A10,$A10)+COUNTIFS($L$2:$L10,"ET",$B$2:$B10,$B10,$A$2:$A10,$A10)),""),"") | J10: =_xlfn.IFNA(IF(VLOOKUP($A10,Spiele!$A$2:$D$16,3,FALSE)=$B10,(COUNTIFS($L$1:$L9,"Tor",$B$1:$B9,$B10,$A$1:$A9,$A10)+COUNTIFS($L$1:$L9,"ET",$B$1:$B9,$B10,$A$1:$A9,$A10))-(COUNTIFS($L$1:$L9,"Tor",$B$1:$B9,"<>"&$B10,$A$1:$A9,$A10)+COUNTIFS($L$1:$L9,"ET",$B$1:$B9,"<>"&$B10,$A$1:$A9,$A10)),(COUNTIFS($L$1:$L9,"Tor",$B$1:$B9,$B10,$A$1:$A9,$A10)+COUNTIFS($L$1:$L9,"ET",$B$1:$B9,$B10,$A$1:$A9,$A10))-(COUNTIFS($L$1:$L9,"Tor",$B$1:$B9,"<>"&$B10,$A$1:$A9,$A10)+COUNTIFS($L$1:$L9,"ET",$B$1:$B9,"<>"&$B10,$A$1:$A9,$A10))),"") -> 2 | K10: 9 | L10: Save | M10: EW | N10: EW | O10: 13 | AA10: adL | AB10: K | AC10: Kopf | AD10: RzT | AE10: 9 | AF10: -17 | AG10: 6.5 | AH10: =IF($L10="ET","",IF($AF10>3.66,SQRT($AG10^2+($AF10-(7.32/2))^2),IF($AF10<-3.66,SQRT($AG10^2+($AF10+(7.32/2))^2),$AG10))) -> 14.839326 | AI10: =IF($L10="ET","",IF(DEGREES(ATAN((7.32*$AG10)/($AG10^2+$AF10^2-(7.32/2)^2)))<=0,180+DEGREES(ATAN((7.32*$AG10)/($AG10^2+$AF10^2-(7.32/2)^2))),DEGREES(ATAN((7.32*$AG10)/($AG10^2+$AF10^2-(7.32/2)^2))))) -> 8.5134601 | AJ10: SB | AK10: -3 | AL10: 1 | AM10: =IF(Abschlüsse[[#This Row],[Ergeb]]="ET","",SQRT(($AF10-$AK10)^2+($AG10-$AL10)^2)) -> 15.041609 | AN10: 2 | AO10: -18 | AP10: 7.5 | AQ10: =IF(AN10=0,"",SQRT(($AF10-$AO10)^2+($AG10-$AP10)^2)) -> 1.4142136 | AR10: 0 | AU10: =IF(AR10=0,"",SQRT(($AF10-$AS10)^2+($AG10-$AT10)^2))
A11: 1 | B11: GWD | C11: =IF($A11="","",IF(VLOOKUP($A11,Spiele!$A$2:$D$16,3,FALSE)=$B11,"H","G")) -> G | D11: =IF($B11="","",IF(VLOOKUP($A11,Spiele!$A$2:$F$16,3,FALSE)=$B11,VLOOKUP($A11,Spiele!$A$2:$F$16,4,FALSE),VLOOKUP($A11,Spiele!$A$2:$F$16,3,FALSE))) -> FCN | E11: =IF(Abschlüsse[[#This Row],[Ergeb]]="ET",0,COUNTIFS($A$2:$A11,$A11,$B$2:$B11,$B11,$L$2:$L11,"<>ET")) -> 4 | F11: 24 | G11: 1 | H11: =COUNTIFS('Rote Karten'!$A$2:$A$4,$A11,'Rote Karten'!$D$2:$D$4,"<>"&$B11,'Rote Karten'!$B$2:$B$4,"<"&$F11,'Rote Karten'!$C$2:$C$4,"<="&$G11)-COUNTIFS('Rote Karten'!$A$2:$A$4,$A11,'Rote Karten'!$D$2:$D$4,$B11,'Rote Karten'!$B$2:$B$4,"<"&$F11,'Rote Karten'!$C$2:$C$4,"<="&$G11) -> 0 | I11: =IF(OR($L11="Tor",$L11="ET"),_xlfn.IFNA(IF(VLOOKUP($A11,Spiele!$A$2:$C$16,3,FALSE)=$B11,COUNTIFS($L$2:$L11,"Tor",$B$2:$B11,$B11,$A$2:$A11,$A11)+COUNTIFS($L$2:$L11,"ET",$B$2:$B11,$B11,$A$2:$A11,$A11)&":"&COUNTIFS($L$2:$L11,"Tor",$B$2:$B11,"<>"&$B11,$A$2:$A11,$A11)+COUNTIFS($L$2:$L11,"ET",$B$2:$B11,"<>"&$B11,$A$2:$A11,$A11),COUNTIFS($L$2:$L11,"Tor",$B$2:$B11,"<>"&$B11,$A$2:$A11,$A11)+COUNTIFS($L$2:$L11,"ET",$B$2:$B11,"<>"&$B11,$A$2:$A11,$A11)&":"&COUNTIFS($L$2:$L11,"Tor",$B$2:$B11,$B11,$A$2:$A11,$A11)+COUNTIFS($L$2:$L11,"ET",$B$2:$B11,$B11,$A$2:$A11,$A11)),""),"") | J11: =_xlfn.IFNA(IF(VLOOKUP($A11,Spiele!$A$2:$D$16,3,FALSE)=$B11,(COUNTIFS($L$1:$L10,"Tor",$B$1:$B10,$B11,$A$1:$A10,$A11)+COUNTIFS($L$1:$L10,"ET",$B$1:$B10,$B11,$A$1:$A10,$A11))-(COUNTIFS($L$1:$L10,"Tor",$B$1:$B10,"<>"&$B11,$A$1:$A10,$A11)+COUNTIFS($L$1:$L10,"ET",$B$1:$B10,"<>"&$B11,$A$1:$A10,$A11)),(COUNTIFS($L$1:$L10,"Tor",$B$1:$B10,$B11,$A$1:$A10,$A11)+COUNTIFS($L$1:$L10,"ET",$B$1:$B10,$B11,$A$1:$A10,$A11))-(COUNTIFS($L$1:$L10,"Tor",$B$1:$B10,"<>"&$B11,$A$1:$A10,$A11)+COUNTIFS($L$1:$L10,"ET",$B$1:$B10,"<>"&$B11,$A$1:$A10,$A11))),"") -> -2 | K11: 10 | L11: Save | M11: USO | N11: D | AA11: nd | AB11: L | AC11: Fuß | AD11: BzT | AF11: -5.5 | AG11: 15.5 | AH11: =IF($L11="ET","",IF($AF11>3.66,SQRT($AG11^2+($AF11-(7.32/2))^2),IF($AF11<-3.66,SQRT($AG11^2+($AF11+(7.32/2))^2),$AG11))) -> 15.608831 | AI11: =IF($L11="ET","",IF(DEGREES(ATAN((7.32*$AG11)/($AG11^2+$AF11^2-(7.32/2)^2)))<=0,180+DEGREES(ATAN((7.32*$AG11)/($AG11^2+$AF11^2-(7.32/2)^2))),DEGREES(ATAN((7.32*$AG11)/($AG11^2+$AF11^2-(7.32/2)^2))))) -> 23.811836 | AJ11: SB | AK11: -3.5 | AL11: 8 | AM11: =IF(Abschlüsse[[#This Row],[Ergeb]]="ET","",SQRT(($AF11-$AK11)^2+($AG11-$AL11)^2)) -> 7.7620873 | AN11: 2 | AO11: -4.5 | AP11: 17.5 | AQ11: =IF(AN11=0,"",SQRT(($AF11-$AO11)^2+($AG11-$AP11)^2)) -> 2.236068 | AR11: 0 | AU11: =IF(AR11=0,"",SQRT(($AF11-$AS11)^2+($AG11-$AT11)^2))
A12: 1 | B12: GWD | C12: =IF($A12="","",IF(VLOOKUP($A12,Spiele!$A$2:$D$16,3,FALSE)=$B12,"H","G")) -> G | D12: =IF($B12="","",IF(VLOOKUP($A12,Spiele!$A$2:$F$16,3,FALSE)=$B12,VLOOKUP($A12,Spiele!$A$2:$F$16,4,FALSE),VLOOKUP($A12,Spiele!$A$2:$F$16,3,FALSE))) -> FCN | E12: =IF(Abschlüsse[[#This Row],[Ergeb]]="ET",0,COUNTIFS($A$2:$A12,$A12,$B$2:$B12,$B12,$L$2:$L12,"<>ET")) -> 5 | F12: 24 | G12: 1 | H12: =COUNTIFS('Rote Karten'!$A$2:$A$4,$A12,'Rote Karten'!$D$2:$D$4,"<>"&$B12,'Rote Karten'!$B$2:$B$4,"<"&$F12,'Rote Karten'!$C$2:$C$4,"<="&$G12)-COUNTIFS('Rote Karten'!$A$2:$A$4,$A12,'Rote Karten'!$D$2:$D$4,$B12,'Rote Karten'!$B$2:$B$4,"<"&$F12,'Rote Karten'!$C$2:$C$4,"<="&$G12) -> 0 | I12: =IF(OR($L12="Tor",$L12="ET"),_xlfn.IFNA(IF(VLOOKUP($A12,Spiele!$A$2:$C$16,3,FALSE)=$B12,COUNTIFS($L$2:$L12,"Tor",$B$2:$B12,$B12,$A$2:$A12,$A12)+COUNTIFS($L$2:$L12,"ET",$B$2:$B12,$B12,$A$2:$A12,$A12)&":"&COUNTIFS($L$2:$L12,"Tor",$B$2:$B12,"<>"&$B12,$A$2:$A12,$A12)+COUNTIFS($L$2:$L12,"ET",$B$2:$B12,"<>"&$B12,$A$2:$A12,$A12),COUNTIFS($L$2:$L12,"Tor",$B$2:$B12,"<>"&$B12,$A$2:$A12,$A12)+COUNTIFS($L$2:$L12,"ET",$B$2:$B12,"<>"&$B12,$A$2:$A12,$A12)&":"&COUNTIFS($L$2:$L12,"Tor",$B$2:$B12,$B12,$A$2:$A12,$A12)+COUNTIFS($L$2:$L12,"ET",$B$2:$B12,$B12,$A$2:$A12,$A12)),""),"") | J12: =_xlfn.IFNA(IF(VLOOKUP($A12,Spiele!$A$2:$D$16,3,FALSE)=$B12,(COUNTIFS($L$1:$L11,"Tor",$B$1:$B11,$B12,$A$1:$A11,$A12)+COUNTIFS($L$1:$L11,"ET",$B$1:$B11,$B12,$A$1:$A11,$A12))-(COUNTIFS($L$1:$L11,"Tor",$B$1:$B11,"<>"&$B12,$A$1:$A11,$A12)+COUNTIFS($L$1:$L11,"ET",$B$1:$B11,"<>"&$B12,$A$1:$A11,$A12)),(COUNTIFS($L$1:$L11,"Tor",$B$1:$B11,$B12,$A$1:$A11,$A12)+COUNTIFS($L$1:$L11,"ET",$B$1:$B11,$B12,$A$1:$A11,$A12))-(COUNTIFS($L$1:$L11,"Tor",$B$1:$B11,"<>"&$B12,$A$1:$A11,$A12)+COUNTIFS($L$1:$L11,"ET",$B$1:$B11,"<>"&$B12,$A$1:$A11,$A12))),"") -> -2 | K12: 10 | L12: TLK | M12: USO | N12: NS | AA12: As | AB12: R | AC12: Fuß | AD12: adD | AF12: 6.5 | AG12: 12 | AH12: =IF($L12="ET","",IF($AF12>3.66,SQRT($AG12^2+($AF12-(7.32/2))^2),IF($AF12<-3.66,SQRT($AG12^2+($AF12+(7.32/2))^2),$AG12))) -> 12.331488 | AI12: =IF($L12="ET","",IF(DEGREES(ATAN((7.32*$AG12)/($AG12^2+$AF12^2-(7.32/2)^2)))<=0,180+DEGREES(ATAN((7.32*$AG12)/($AG12^2+$AF12^2-(7.32/2)^2))),DEGREES(ATAN((7.32*$AG12)/($AG12^2+$AF12^2-(7.32/2)^2))))) -> 26.938464 | AJ12: niT | AM12: =IF(Abschlüsse[[#This Row],[Ergeb]]="ET","",SQRT(($AF12-$AK12)^2+($AG12-$AL12)^2)) -> 13.647344 | AN12: 1 | AO12: 4 | AP12: 11.5 | AQ12: =IF(AN12=0,"",SQRT(($AF12-$AO12)^2+($AG12-$AP12)^2)) -> 2.5495098 | AR12: 1 | AS12: 0 | AT12: 7 | AU12: =IF(AR12=0,"",SQRT(($AF12-$AS12)^2+($AG12-$AT12)^2)) -> 8.2006097
A13: 1 | B13: GWD | C13: =IF($A13="","",IF(VLOOKUP($A13,Spiele!$A$2:$D$16,3,FALSE)=$B13,"H","G")) -> G | D13: =IF($B13="","",IF(VLOOKUP($A13,Spiele!$A$2:$F$16,3,FALSE)=$B13,VLOOKUP($A13,Spiele!$A$2:$F$16,4,FALSE),VLOOKUP($A13,Spiele!$A$2:$F$16,3,FALSE))) -> FCN | E13: =IF(Abschlüsse[[#This Row],[Ergeb]]="ET",0,COUNTIFS($A$2:$A13,$A13,$B$2:$B13,$B13,$L$2:$L13,"<>ET")) -> 6 | F13: 27 | G13: 1 | H13: =COUNTIFS('Rote Karten'!$A$2:$A$4,$A13,'Rote Karten'!$D$2:$D$4,"<>"&$B13,'Rote Karten'!$B$2:$B$4,"<"&$F13,'Rote Karten'!$C$2:$C$4,"<="&$G13)-COUNTIFS('Rote Karten'!$A$2:$A$4,$A13,'Rote Karten'!$D$2:$D$4,$B13,'Rote Karten'!$B$2:$B$4,"<"&$F13,'Rote Karten'!$C$2:$C$4,"<="&$G13) -> 0 | I13: =IF(OR($L13="Tor",$L13="ET"),_xlfn.IFNA(IF(VLOOKUP($A13,Spiele!$A$2:$C$16,3,FALSE)=$B13,COUNTIFS($L$2:$L13,"Tor",$B$2:$B13,$B13,$A$2:$A13,$A13)+COUNTIFS($L$2:$L13,"ET",$B$2:$B13,$B13,$A$2:$A13,$A13)&":"&COUNTIFS($L$2:$L13,"Tor",$B$2:$B13,"<>"&$B13,$A$2:$A13,$A13)+COUNTIFS($L$2:$L13,"ET",$B$2:$B13,"<>"&$B13,$A$2:$A13,$A13),COUNTIFS($L$2:$L13,"Tor",$B$2:$B13,"<>"&$B13,$A$2:$A13,$A13)+COUNTIFS($L$2:$L13,"ET",$B$2:$B13,"<>"&$B13,$A$2:$A13,$A13)&":"&COUNTIFS($L$2:$L13,"Tor",$B$2:$B13,$B13,$A$2:$A13,$A13)+COUNTIFS($L$2:$L13,"ET",$B$2:$B13,$B13,$A$2:$A13,$A13)),""),"") | J13: =_xlfn.IFNA(IF(VLOOKUP($A13,Spiele!$A$2:$D$16,3,FALSE)=$B13,(COUNTIFS($L$1:$L12,"Tor",$B$1:$B12,$B13,$A$1:$A12,$A13)+COUNTIFS($L$1:$L12,"ET",$B$1:$B12,$B13,$A$1:$A12,$A13))-(COUNTIFS($L$1:$L12,"Tor",$B$1:$B12,"<>"&$B13,$A$1:$A12,$A13)+COUNTIFS($L$1:$L12,"ET",$B$1:$B12,"<>"&$B13,$A$1:$A12,$A13)),(COUNTIFS($L$1:$L12,"Tor",$B$1:$B12,$B13,$A$1:$A12,$A13)+COUNTIFS($L$1:$L12,"ET",$B$1:$B12,$B13,$A$1:$A12,$A13))-(COUNTIFS($L$1:$L12,"Tor",$B$1:$B12,"<>"&$B13,$A$1:$A12,$A13)+COUNTIFS($L$1:$L12,"ET",$B$1:$B12,"<>"&$B13,$A$1:$A12,$A13))),"") -> -2 | K13: 11 | L13: Vorbei | M13: nFS | N13: AP | AA13: nd | AB13: L | AC13: Fuß | AD13: adD | AF13: 4 | AG13: 33 | AH13: =IF($L13="ET","",IF($AF13>3.66,SQRT($AG13^2+($AF13-(7.32/2))^2),IF($AF13<-3.66,SQRT($AG13^2+($AF13+(7.32/2))^2),$AG13))) -> 33.001751 | AI13: =IF($L13="ET","",IF(DEGREES(ATAN((7.32*$AG13)/($AG13^2+$AF13^2-(7.32/2)^2)))<=0,180+DEGREES(ATAN((7.32*$AG13)/($AG13^2+$AF13^2-(7.32/2)^2))),DEGREES(ATAN((7.32*$AG13)/($AG13^2+$AF13^2-(7.32/2)^2))))) -> 12.477842 | AJ13: SB | AK13: 0.5 | AL13: 2 | AM13: =IF(Abschlüsse[[#This Row],[Ergeb]]="ET","",SQRT(($AF13-$AK13)^2+($AG13-$AL13)^2)) -> 31.196955 | AN13: 1 | AO13: 6.5 | AP13: 32.5 | AQ13: =IF(AN13=0,"",SQRT(($AF13-$AO13)^2+($AG13-$AP13)^2)) -> 2.5495098 | AR13: 3 | AS13: 3.5 | AT13: 23 | AU13: =IF(AR13=0,"",SQRT(($AF13-$AS13)^2+($AG13-$AT13)^2)) -> 10.012492
A14: 1 | B14: FCN | C14: =IF($A14="","",IF(VLOOKUP($A14,Spiele!$A$2:$D$16,3,FALSE)=$B14,"H","G")) -> H | D14: =IF($B14="","",IF(VLOOKUP($A14,Spiele!$A$2:$F$16,3,FALSE)=$B14,VLOOKUP($A14,Spiele!$A$2:$F$16,4,FALSE),VLOOKUP($A14,Spiele!$A$2:$F$16,3,FALSE))) -> GWD | E14: =IF(Abschlüsse[[#This Row],[Ergeb]]="ET",0,COUNTIFS($A$2:$A14,$A14,$B$2:$B14,$B14,$L$2:$L14,"<>ET")) -> 7 | F14: 40 | G14: 1 | H14: =COUNTIFS('Rote Karten'!$A$2:$A$4,$A14,'Rote Karten'!$D$2:$D$4,"<>"&$B14,'Rote Karten'!$B$2:$B$4,"<"&$F14,'Rote Karten'!$C$2:$C$4,"<="&$G14)-COUNTIFS('Rote Karten'!$A$2:$A$4,$A14,'Rote Karten'!$D$2:$D$4,$B14,'Rote Karten'!$B$2:$B$4,"<"&$F14,'Rote Karten'!$C$2:$C$4,"<="&$G14) -> 0 | I14: =IF(OR($L14="Tor",$L14="ET"),_xlfn.IFNA(IF(VLOOKUP($A14,Spiele!$A$2:$C$16,3,FALSE)=$B14,COUNTIFS($L$2:$L14,"Tor",$B$2:$B14,$B14,$A$2:$A14,$A14)+COUNTIFS($L$2:$L14,"ET",$B$2:$B14,$B14,$A$2:$A14,$A14)&":"&COUNTIFS($L$2:$L14,"Tor",$B$2:$B14,"<>"&$B14,$A$2:$A14,$A14)+COUNTIFS($L$2:$L14,"ET",$B$2:$B14,"<>"&$B14,$A$2:$A14,$A14),COUNTIFS($L$2:$L14,"Tor",$B$2:$B14,"<>"&$B14,$A$2:$A14,$A14)+COUNTIFS($L$2:$L14,"ET",$B$2:$B14,"<>"&$B14,$A$2:$A14,$A14)&":"&COUNTIFS($L$2:$L14,"Tor",$B$2:$B14,$B14,$A$2:$A14,$A14)+COUNTIFS($L$2:$L14,"ET",$B$2:$B14,$B14,$A$2:$A14,$A14)),""),"") | J14: =_xlfn.IFNA(IF(VLOOKUP($A14,Spiele!$A$2:$D$16,3,FALSE)=$B14,(COUNTIFS($L$1:$L13,"Tor",$B$1:$B13,$B14,$A$1:$A13,$A14)+COUNTIFS($L$1:$L13,"ET",$B$1:$B13,$B14,$A$1:$A13,$A14))-(COUNTIFS($L$1:$L13,"Tor",$B$1:$B13,"<>"&$B14,$A$1:$A13,$A14)+COUNTIFS($L$1:$L13,"ET",$B$1:$B13,"<>"&$B14,$A$1:$A13,$A14)),(COUNTIFS($L$1:$L13,"Tor",$B$1:$B13,$B14,$A$1:$A13,$A14)+COUNTIFS($L$1:$L13,"ET",$B$1:$B13,$B14,$A$1:$A13,$A14))-(COUNTIFS($L$1:$L13,"Tor",$B$1:$B13,"<>"&$B14,$A$1:$A13,$A14)+COUNTIFS($L$1:$L13,"ET",$B$1:$B13,"<>"&$B14,$A$1:$A13,$A14))),"") -> 2 | K14: 12 | L14: Save | M14: EB | N14: TB | O14: 26 | P14: 23 | AA14: nd | AB14: L | AC14: Fuß | AD14: BzT | AE14: 13 | AF14: -21.5 | AG14: 11.5 | AH14: =IF($L14="ET","",IF($AF14>3.66,SQRT($AG14^2+($AF14-(7.32/2))^2),IF($AF14<-3.66,SQRT($AG14^2+($AF14+(7.32/2))^2),$AG14))) -> 21.225353 | AI14: =IF($L14="ET","",IF(DEGREES(ATAN((7.32*$AG14)/($AG14^2+$AF14^2-(7.32/2)^2)))<=0,180+DEGREES(ATAN((7.32*$AG14)/($AG14^2+$AF14^2-(7.32/2)^2))),DEGREES(ATAN((7.32*$AG14)/($AG14^2+$AF14^2-(7.32/2)^2))))) -> 8.2426483 | AJ14: SB | AK14: -2 | AL14: 2 | AM14: =IF(Abschlüsse[[#This Row],[Ergeb]]="ET","",SQRT(($AF14-$AK14)^2+($AG14-$AL14)^2)) -> 21.691012 | AN14: 1 | AO14: -20.5 | AP14: 12.5 | AQ14: =IF(AN14=0,"",SQRT(($AF14-$AO14)^2+($AG14-$AP14)^2)) -> 1.4142136 | AR14: 0 | AU14: =IF(AR14=0,"",SQRT(($AF14-$AS14)^2+($AG14-$AT14)^2))
A15: 1 | B15: FCN | C15: =IF($A15="","",IF(VLOOKUP($A15,Spiele!$A$2:$D$16,3,FALSE)=$B15,"H","G")) -> H | D15: =IF($B15="","",IF(VLOOKUP($A15,Spiele!$A$2:$F$16,3,FALSE)=$B15,VLOOKUP($A15,Spiele!$A$2:$F$16,4,FALSE),VLOOKUP($A15,Spiele!$A$2:$F$16,3,FALSE))) -> GWD | E15: =IF(Abschlüsse[[#This Row],[Ergeb]]="ET",0,COUNTIFS($A$2:$A15,$A15,$B$2:$B15,$B15,$L$2:$L15,"<>ET")) -> 8 | F15: 40 | G15: 1 | H15: =COUNTIFS('Rote Karten'!$A$2:$A$4,$A15,'Rote Karten'!$D$2:$D$4,"<>"&$B15,'Rote Karten'!$B$2:$B$4,"<"&$F15,'Rote Karten'!$C$2:$C$4,"<="&$G15)-COUNTIFS('Rote Karten'!$A$2:$A$4,$A15,'Rote Karten'!$D$2:$D$4,$B15,'Rote Karten'!$B$2:$B$4,"<"&$F15,'Rote Karten'!$C$2:$C$4,"<="&$G15) -> 0 | I15: =IF(OR($L15="Tor",$L15="ET"),_xlfn.IFNA(IF(VLOOKUP($A15,Spiele!$A$2:$C$16,3,FALSE)=$B15,COUNTIFS($L$2:$L15,"Tor",$B$2:$B16,$B15,$A$2:$A16,$A15)+COUNTIFS($L$2:$L15,"ET",$B$2:$B16,$B15,$A$2:$A16,$A15)&":"&COUNTIFS($L$2:$L15,"Tor",$B$2:$B16,"<>"&$B15,$A$2:$A16,$A15)+COUNTIFS($L$2:$L15,"ET",$B$2:$B16,"<>"&$B15,$A$2:$A16,$A15),COUNTIFS($L$2:$L15,"Tor",$B$2:$B16,"<>"&$B15,$A$2:$A16,$A15)+COUNTIFS($L$2:$L15,"ET",$B$2:$B16,"<>"&$B15,$A$2:$A16,$A15)&":"&COUNTIFS($L$2:$L15,"Tor",$B$2:$B16,$B15,$A$2:$A16,$A15)+COUNTIFS($L$2:$L15,"ET",$B$2:$B16,$B15,$A$2:$A16,$A15)),""),"") | J15: =_xlfn.IFNA(IF(VLOOKUP($A15,Spiele!$A$2:$D$16,3,FALSE)=$B15,(COUNTIFS($L$1:$L14,"Tor",$B$1:$B14,$B15,$A$1:$A14,$A15)+COUNTIFS($L$1:$L14,"ET",$B$1:$B14,$B15,$A$1:$A14,$A15))-(COUNTIFS($L$1:$L14,"Tor",$B$1:$B14,"<>"&$B15,$A$1:$A14,$A15)+COUNTIFS($L$1:$L14,"ET",$B$1:$B14,"<>"&$B15,$A$1:$A14,$A15)),(COUNTIFS($L$1:$L14,"Tor",$B$1:$B14,$B15,$A$1:$A14,$A15)+COUNTIFS($L$1:$L14,"ET",$B$1:$B14,$B15,$A$1:$A14,$A15))-(COUNTIFS($L$1:$L14,"Tor",$B$1:$B14,"<>"&$B15,$A$1:$A14,$A15)+COUNTIFS($L$1:$L14,"ET",$B$1:$B14,"<>"&$B15,$A$1:$A14,$A15))),"") -> 2 | K15: 12 | L15: Block | M15: EB | N15: NS | AA15: As | AB15: R | AC15: Fuß | AD15: BzT | AE15: 11 | AF15: 11 | AG15: 10 | AH15: =IF($L15="ET","",IF($AF15>3.66,SQRT($AG15^2+($AF15-(7.32/2))^2),IF($AF15<-3.66,SQRT($AG15^2+($AF15+(7.32/2))^2),$AG15))) -> 12.40466 | AI15: =IF($L15="ET","",IF(DEGREES(ATAN((7.32*$AG15)/($AG15^2+$AF15^2-(7.32/2)^2)))<=0,180+DEGREES(ATAN((7.32*$AG15)/($AG15^2+$AF15^2-(7.32/2)^2))),DEGREES(ATAN((7.32*$AG15)/($AG15^2+$AF15^2-(7.32/2)^2))))) -> 19.422328 | AJ15: SB | AK15: 1.5 | AL15: 2.5 | AM15: =IF(Abschlüsse[[#This Row],[Ergeb]]="ET","",SQRT(($AF15-$AK15)^2+($AG15-$AL15)^2)) -> 12.103718 | AN15: 0 | AQ15: =IF(AN15=0,"",SQRT(($AF15-$AO15)^2+($AG15-$AP15)^2)) | AR15: 2 | AS15: 8 | AT15: 6.5 | AU15: =IF(AR15=0,"",SQRT(($AF15-$AS15)^2+($AG15-$AT15)^2)) -> 4.6097722
A16: 1 | B16: FCN | C16: =IF($A16="","",IF(VLOOKUP($A16,Spiele!$A$2:$D$16,3,FALSE)=$B16,"H","G")) -> H | D16: =IF($B16="","",IF(VLOOKUP($A16,Spiele!$A$2:$F$16,3,FALSE)=$B16,VLOOKUP($A16,Spiele!$A$2:$F$16,4,FALSE),VLOOKUP($A16,Spiele!$A$2:$F$16,3,FALSE))) -> GWD | E16: =IF(Abschlüsse[[#This Row],[Ergeb]]="ET",0,COUNTIFS($A$2:$A16,$A16,$B$2:$B16,$B16,$L$2:$L16,"<>ET")) -> 9 | F16: 41 | G16: 2 | H16: =COUNTIFS('Rote Karten'!$A$2:$A$4,$A16,'Rote Karten'!$D$2:$D$4,"<>"&$B16,'Rote Karten'!$B$2:$B$4,"<"&$F16,'Rote Karten'!$C$2:$C$4,"<="&$G16)-COUNTIFS('Rote Karten'!$A$2:$A$4,$A16,'Rote Karten'!$D$2:$D$4,$B16,'Rote Karten'!$B$2:$B$4,"<"&$F16,'Rote Karten'!$C$2:$C$4,"<="&$G16) -> 0 | I16: =IF(OR($L16="Tor",$L16="ET"),_xlfn.IFNA(IF(VLOOKUP($A16,Spiele!$A$2:$C$16,3,FALSE)=$B16,COUNTIFS($L$2:$L16,"Tor",$B$2:$B16,$B16,$A$2:$A16,$A16)+COUNTIFS($L$2:$L16,"ET",$B$2:$B16,$B16,$A$2:$A16,$A16)&":"&COUNTIFS($L$2:$L16,"Tor",$B$2:$B16,"<>"&$B16,$A$2:$A16,$A16)+COUNTIFS($L$2:$L16,"ET",$B$2:$B16,"<>"&$B16,$A$2:$A16,$A16),COUNTIFS($L$2:$L16,"Tor",$B$2:$B16,"<>"&$B16,$A$2:$A16,$A16)+COUNTIFS($L$2:$L16,"ET",$B$2:$B16,"<>"&$B16,$A$2:$A16,$A16)&":"&COUNTIFS($L$2:$L16,"Tor",$B$2:$B16,$B16,$A$2:$A16,$A16)+COUNTIFS($L$2:$L16,"ET",$B$2:$B16,$B16,$A$2:$A16,$A16)),""),"") | J16: =_xlfn.IFNA(IF(VLOOKUP($A16,Spiele!$A$2:$D$16,3,FALSE)=$B16,(COUNTIFS($L$1:$L15,"Tor",$B$1:$B15,$B16,$A$1:$A15,$A16)+COUNTIFS($L$1:$L15,"ET",$B$1:$B15,$B16,$A$1:$A15,$A16))-(COUNTIFS($L$1:$L15,"Tor",$B$1:$B15,"<>"&$B16,$A$1:$A15,$A16)+COUNTIFS($L$1:$L15,"ET",$B$1:$B15,"<>"&$B16,$A$1:$A15,$A16)),(COUNTIFS($L$1:$L15,"Tor",$B$1:$B15,$B16,$A$1:$A15,$A16)+COUNTIFS($L$1:$L15,"ET",$B$1:$B15,$B16,$A$1:$A15,$A16))-(COUNTIFS($L$1:$L15,"Tor",$B$1:$B15,"<>"&$B16,$A$1:$A15,$A16)+COUNTIFS($L$1:$L15,"ET",$B$1:$B15,"<>"&$B16,$A$1:$A15,$A16))),"") -> 2 | K16: 13 | L16: Block | M16: USO | N16: RP | O16: 27 | P16: 9 | Q16: 6 | AA16: nd | AB16: L | AC16: Fuß | AD16: adD | AE16: 9 | AF16: -7.5 | AG16: 18 | AH16: =IF($L16="ET","",IF($AF16>3.66,SQRT($AG16^2+($AF16-(7.32/2))^2),IF($AF16<-3.66,SQRT($AG16^2+($AF16+(7.32/2))^2),$AG16))) -> 18.405043 | AI16: =IF($L16="ET","",IF(DEGREES(ATAN((7.32*$AG16)/($AG16^2+$AF16^2-(7.32/2)^2)))<=0,180+DEGREES(ATAN((7.32*$AG16)/($AG16^2+$AF16^2-(7.32/2)^2))),DEGREES(ATAN((7.32*$AG16)/($AG16^2+$AF16^2-(7.32/2)^2))))) -> 19.756338 | AJ16: SB | AK16: -2 | AL16: 2 | AM16: =IF(Abschlüsse[[#This Row],[Ergeb]]="ET","",SQRT(($AF16-$AK16)^2+($AG16-$AL16)^2)) -> 16.918924 | AN16: 0 | AQ16: =IF(AN16=0,"",SQRT(($AF16-$AO16)^2+($AG16-$AP16)^2)) | AR16: 1 | AS16: -6.5 | AT16: 16 | AU16: =IF(AR16=0,"",SQRT(($AF16-$AS16)^2+($AG16-$AT16)^2)) -> 2.236068
